Workbook

Sheet Synthèse
A1: Situation actuelle 2024
B2: Parquet | C2: PR | D2: PRA | E2: PAP | F2: PMF | G2: DEF | H2: COFAC | I2: EP | J2: PCSNE | K2: Pciv | L2: SG
A3: ETPT mag. Parquet | B3: 39 | C3: 1 | D3: 5 | E3: 8 | F3: 6.3 | G3: 6 | H3: 4 | I3: 4 | J3: 2 | K3: 2 | L3: 1
A4: ETPT de perm/audiences | B4: 33 | C4: 1 | E4: 8 | F4: 6 | G4: 6 | H4: 4 | I4: 4 | J4: 2 | K4: 2 | L4: 1
A5: total 1/2 journées (hors Hier.) | B5: =(B3-7)*25 -> 800 | C5: =C3*25 -> 25 | D5: =D3*25 -> 125 | E5: =E3*25 -> 200 | F5: =F3*25 -> 157.5 | G5: =G3*25 -> 150 | H5: =H3*25 -> 100 | I5: =I3*25 -> 100 | J5: =J3*25 -> 50 | ... L5: =L3*25 -> 25
A7: 1/2 j d'audiences (Tcorr, TPE, Tpol, Tcom.) | B7: 156 | C7: =(COUNTIF($C$4:$AA$33,$AF$35)) -> 4 | E7: =(COUNTIF($C$4:$AA$35,$AH$35)) -> 48 | F7: =(COUNTIF($C$4:$AA$35,$AI$35)) -> 46 | G7: =(COUNTIF($C$4:$AA$35,$AJ$35)) -> 42 | H7: =(COUNTIF($C$4:$AA$35,$AK$35)) -> 16 | I7: =(COUNTIF($C$4:$AA$35,$AL$35)) -> 29 | J7: =(COUNTIF($C$4:$AA$35,$AM$35)) -> 4 | K7: =(COUNTIF($C$4:$AA$35,$AN$35)) -> 13 | L7: =(COUNTIF($C$4:$AA$35,"SG")) -> 1
A8: Pondération (jour) | B8: =E8+F8+G8+H8+I8+K8+C8+J8+L8 -> 216.5 | C8: =COUNTIF($C$4:$AA$4,$AF$35)*$AB$4+COUNTIF($C$5:$AA$5,$AF$35)*$AB$5+COUNTIF($C$6:$AA$6,$AF$35)*$AB$6+COUNTIF($C$7:$AA$7,$AF$35)*$AB$7+COUNTIF($C$8:$AA$8,$AF$35)*$AB$8+COUNTIF($C$9:$AA$9,$AF$35)*$AB$9+COUNTIF($C$10:$AA$10,$AF$35)*$AB$10+COUNTIF($C$11:$AA$11,$AF$35)*$AB$11+COUNTIF($C$12:$AA$12,$AF$35)*$AB$12+COUNTIF($C$13:$AA$13,$AF$35)*$AB$13+COUNTIF($C$14:$AA$14,$AF$35)*$AB$14+COUNTIF($C$15:$AA$15,$AF$35)*$AB$15+COUNTIF($C$16:$AA$16,$AF$35)*$AB$16+COUNTIF($C$17:$AA$17,$AF$35)*$AB$17+COUNTIF($C$18:$AA$18,$AF$35)*$AB$18+COUNTIF($C$19:$AA$19,$AF$35)*$AB$19+COUNTIF($C$20:$AA$20,$AF$35)*$AB$20+COUNTIF($C$21:$AA$21,$AF$35)*$AB$21+COUNTIF($C$22:$AA$22,$AF$35)*$AB$22+COUNTIF($C$23:$AA$23,$AF$35)*$AB$23+COUNTIF($C$24:$AA$24,$AF$35)*$AB$24+COUNTIF($C$25:$AA$25,$AF$35)*$AB$25+COUNTIF($C$26:$AA$26,$AF$35)*$AB$26+COUNTIF($C$27:$AA$27,$AF$35)*$AB$27+COUNTIF($C$28:$AA$28,$AF$35)*$AB$28+COUNTIF($C$29:$AA$29,$AF$35)*$AB$29+COUNTIF($C$30:$AA$30,$AF$35)*$AB$30+COUNTIF($C$31:$AA$31,$AF$35)*$AB$31+COUNTIF($C$32:$AA$32,$AF$35)*$AB$32+COUNTIF($C$33:$AA$33,$AF$35)*$AB$33+COUNTIF($C$34:$AA$34,$AF$35)*$AB$34 -> 2 | D8: =4+4+4.25+7.125+3.25 -> 22.625 | E8: =COUNTIF($C$4:$AA$4,$AH$35)*$AB$4+COUNTIF($C$5:$AA$5,$AH$35)*$AB$5+COUNTIF($C$6:$AA$6,$AH$35)*$AB$6+COUNTIF($C$7:$AA$7,$AH$35)*$AB$7+COUNTIF($C$8:$AA$8,$AH$35)*$AB$8+COUNTIF($C$9:$AA$9,$AH$35)*$AB$9+COUNTIF($C$10:$AA$10,$AH$35)*$AB$10+COUNTIF($C$11:$AA$11,$AH$35)*$AB$11+COUNTIF($C$12:$AA$12,$AH$35)*$AB$12+COUNTIF($C$13:$AA$13,$AH$35)*$AB$13+COUNTIF($C$14:$AA$14,$AH$35)*$AB$14+COUNTIF($C$15:$AA$15,$AH$35)*$AB$15+COUNTIF($C$16:$AA$16,$AH$35)*$AB$16+COUNTIF($C$17:$AA$17,$AH$35)*$AB$17+COUNTIF($C$18:$AA$18,$AH$35)*$AB$18+COUNTIF($C$19:$AA$19,$AH$35)*$AB$19+COUNTIF($C$20:$AA$20,$AH$35)*$AB$20+COUNTIF($C$21:$AA$21,$AH$35)*$AB$21+COUNTIF($C$22:$AA$22,$AH$35)*$AB$22+COUNTIF($C$23:$AA$23,$AH$35)*$AB$23+COUNTIF($C$24:$AA$24,$AH$35)*$AB$24+COUNTIF($C$25:$AA$25,$AH$35)*$AB$25+COUNTIF($C$26:$AA$26,$AH$35)*$AB$26+COUNTIF($C$27:$AA$27,$AH$35)*$AB$27+COUNTIF($C$28:$AA$28,$AH$35)*$AB$28+COUNTIF($C$29:$AA$29,$AH$35)*$AB$29+COUNTIF($C$30:$AA$30,$AH$35)*$AB$30+COUNTIF($C$31:$AA$31,$AH$35)*$AB$31+COUNTIF($C$32:$AA$32,$AH$35)*$AB$32+COUNTIF($C$33:$AA$33,$AH$35)*$AB$33+COUNTIF($C$34:$AA$34,$AH$35)*$AB$34 -> 52.5 | F8: =COUNTIF($C$4:$AA$4,F2)*$AB$4+COUNTIF($C$5:$AA$5,$AI$35)*$AB$5+COUNTIF($C$6:$AA$6,$AI$35)*$AB$6+COUNTIF($C$7:$AA$7,$AI$35)*$AB$7+COUNTIF($C$8:$AA$8,$AI$35)*$AB$8++COUNTIF($C$9:$AA$9,$AI$35)*$AB$9+COUNTIF($C$10:$AA$10,$AI$35)*$AB$10+COUNTIF($C$11:$AA$11,$AI$35)*0.5*$AB$11+COUNTIF($C$12:$AA$12,$AI$35)*$AB$12+COUNTIF($C$13:$AA$13,$AI$35)*$AB$13+COUNTIF($C$14:$AA$14,$AI$35)*$AB$14+COUNTIF($C$15:$AA$15,$AI$35)*$AB$15+COUNTIF($C$16:$AA$16,$AI$35)*$AB$16+COUNTIF($C$17:$AA$17,$AI$35)*$AB$17+COUNTIF($C$18:$AA$18,$AI$35)*$AB$18+COUNTIF($C$19:$AA$19,$AI$35)*$AB$19+COUNTIF($C$20:$AA$20,$AI$35)*$AB$20+COUNTIF($C$21:$AA$21,$AI$35)*$AB$21+COUNTIF($C$22:$AA$22,$AI$35)*$AB$22+COUNTIF($C$23:$AA$23,$AI$35)*$AB$23+COUNTIF($C$24:$AA$24,$AI$35)*$AB$24+COUNTIF($C$25:$AA$25,$AI$35)*$AB$25+COUNTIF($C$26:$AA$26,$AI$35)*$AB$26+COUNTIF($C$27:$AA$27,$AI$35)*$AB$27+COUNTIF($C$28:$AA$28,$AI$35)*$AB$28+COUNTIF($C$29:$AA$29,$AI$35)*$AB$29+COUNTIF($C$30:$AA$30,$AI$35)*$AB$30+COUNTIF($C$31:$AA$31,$AI$35)*$AB$31+COUNTIF($C$32:$AA$32,$AI$35)*$AB$32+COUNTIF($C$33:$AA$33,$AI$35)*$AB$33+COUNTIF($C$34:$AA$34,$AI$35)*$AB$34 -> 48.75 | G8: =COUNTIF($C$4:$AA$4,$AJ$35)*$AB$4+COUNTIF($C$5:$AA$5,$AJ$35)*$AB$5+COUNTIF($C$6:$AA$6,$AJ$35)*$AB$6+COUNTIF($C$7:$AA$7,$AJ$35)*$AB$7+COUNTIF($C$8:$AA$8,$AJ$35)*$AB$8+COUNTIF($C$9:$AA$9,$AJ$35)*$AB$9+COUNTIF($C$10:$AA$10,$AJ$35)*$AB$10+COUNTIF($C$11:$AA$11,$AJ$35)*$AB$11+COUNTIF($C$12:$AA$12,$AJ$35)*$AB$12+COUNTIF($C$13:$AA$13,$AJ$35)*$AB$13+COUNTIF($C$14:$AA$14,$AJ$35)*$AB$14+COUNTIF($C$15:$AA$15,$AJ$35)*$AB$15+COUNTIF($C$16:$AA$16,$AJ$35)*$AB$16+COUNTIF($C$17:$AA$17,$AJ$35)*$AB$17+COUNTIF($C$18:$AA$18,$AJ$35)*$AB$18+COUNTIF($C$19:$AA$19,$AJ$35)*$AB$19+COUNTIF($C$20:$AA$20,$AJ$35)*$AB$20+COUNTIF($C$21:$AA$21,$AJ$35)*$AB$21+COUNTIF($C$22:$AA$22,$AJ$35)*$AB$22+COUNTIF($C$23:$AA$23,$AJ$35)*$AB$23+COUNTIF($C$24:$AA$24,$AJ$35)*$AB$24+COUNTIF($C$25:$AA$25,$AJ$35)*$AB$25+COUNTIF($C$26:$AA$26,$AJ$35)*$AB$26+COUNTIF($C$27:$AA$27,$AJ$35)*$AB$27+COUNTIF($C$28:$AA$28,$AJ$35)*$AB$28+COUNTIF($C$29:$AA$29,$AJ$35)*$AB$29+COUNTIF($C$30:$AA$30,$AJ$35)*$AB$96+COUNTIF($C$31:$AA$31,$AJ$35)*$AB$31+COUNTIF($C$32:$AA$32,$AJ$35)*$AB$32+COUNTIF($C$33:$AA$33,$AJ$35)*$AB$33+COUNTIF($C$34:$AA$34,$AJ$35)*$AB$34 -> 46 | H8: =COUNTIF($C$4:$AA$4,$AK$35)*$AB$4+COUNTIF($C$5:$AA$5,$AK$35)*$AB$5+COUNTIF($C$6:$AA$6,$AK$35)*$AB$6+COUNTIF($C$7:$AA$7,$AK$35)*$AB$7+COUNTIF($C$8:$AA$8,$AK$35)*$AB$8+COUNTIF($C$9:$AA$9,$AK$35)*$AB$9+COUNTIF($C$10:$AA$10,$AK$35)*$AB$10+COUNTIF($C$11:$AA$11,$AK$35)*$AB$11+COUNTIF($C$12:$AA$12,$AK$35)*$AB$12+COUNTIF($C$13:$AA$13,$AK$35)*$AB$13+COUNTIF($C$14:$AA$14,$AK$35)*$AB$14+COUNTIF($C$15:$AA$15,$AK$35)*$AB$15+COUNTIF($C$16:$AA$16,$AK$35)*$AB$16+COUNTIF($C$17:$AA$17,$AK$35)*$AB$17+COUNTIF($C$18:$AA$18,$AK$35)*$AB$18+COUNTIF($C$19:$AA$19,$AK$35)*$AB$19+COUNTIF($C$20:$AA$20,$AK$35)*$AB$20+COUNTIF($C$21:$AA$21,$AK$35)*$AB$21+COUNTIF($C$22:$AA$22,$AK$35)*$AB$22+COUNTIF($C$23:$AA$23,$AK$35)*$AB$23+COUNTIF($C$24:$AA$24,$AK$35)*$AB$24+COUNTIF($C$25:$AA$25,$AK$35)*$AB$25+COUNTIF($C$26:$AA$26,$AK$35)*$AB$26+COUNTIF($C$27:$AA$27,$AK$35)*$AB$27+COUNTIF($C$28:$AA$28,$AK$35)*$AB$28+COUNTIF($C$29:$AA$29,$AK$35)*$AB$29+COUNTIF($C$30:$AA$30,$AK$35)*$AB$30+COUNTIF($C$31:$AA$31,$AK$35)*$AB$31+COUNTIF($C$32:$AA$32,$AK$35)*$AB$32+COUNTIF($C$33:$AA$33,$AK$35)*$AB$33+COUNTIF($C$34:$AA$34,$AK$35)*$AB$34 -> 21.75 | I8: =COUNTIF($C$4:$AA$4,$AL$35)*$AB$4+COUNTIF($C$5:$AA$5,$AL$35)*$AB$5+COUNTIF($C$6:$AA$6,$AL$35)*$AB$6+COUNTIF($C$7:$AA$7,$AL$35)*$AB$7+COUNTIF($C$8:$AA$8,$AL$35)*$AB$8+COUNTIF($C$9:$AA$9,$AL$35)*$AB$9+COUNTIF($C$10:$AA$10,$AL$35)*$AB$10+COUNTIF($C$11:$AA$11,$AL$35)*$AB$11+COUNTIF($C$12:$AA$12,$AL$35)*$AB$12+COUNTIF($C$13:$AA$13,$AL$35)*$AB$13+COUNTIF($C$14:$AA$14,$AL$35)*$AB$14+COUNTIF($C$15:$AA$15,$AL$35)*$AB$15+COUNTIF($C$16:$AA$16,$AL$35)*$AB$16+COUNTIF($C$17:$AA$17,$AL$35)*$AB$17+COUNTIF($C$18:$AA$18,$AL$35)*$AB$18+COUNTIF($C$19:$AA$19,$AL$35)*$AB$19+COUNTIF($C$20:$AA$20,$AL$35)*$AB$20+COUNTIF($C$21:$AA$21,$AL$35)*$AB$21+COUNTIF($C$22:$AA$22,$AL$35)*$AB$22+COUNTIF($C$23:$AA$23,$AL$35)*$AB$23+COUNTIF($C$24:$AA$24,$AL$35)*$AB$24+COUNTIF($C$25:$AA$25,$AL$35)*$AB$25+COUNTIF($C$26:$AA$26,$AL$35)*$AB$26+COUNTIF($C$27:$AA$27,$AL$35)*$AB$27+COUNTIF($C$28:$AA$28,$AL$35)*$AB$28+COUNTIF($C$29:$AA$29,$AL$35)*$AB$29+COUNTIF($C$30:$AA$30,$AL$35)*$AB$30+COUNTIF($C$31:$AA$31,$AL$35)*$AB$31+COUNTIF($C$32:$AA$32,$AL$35)*$AB$32+COUNTIF($C$33:$AA$33,$AL$35)*$AB$33+COUNTIF($C$34:$AA$34,$AL$35)*$AB$34 -> 27.25 | J8: =COUNTIF($C$4:$AA$4,$AM$35)*$AB$4+COUNTIF($C$5:$AA$5,$AM$35)*$AB$5+COUNTIF($C$6:$AA$6,$AM$35)*$AB$6+COUNTIF($C$7:$AA$7,$AM$35)*$AB$7+COUNTIF($C$8:$AA$8,$AM$35)*$AB$8+COUNTIF($C$9:$AA$9,$AM$35)*$AB$9+COUNTIF($C$10:$AA$10,$AM$35)*$AB$10+COUNTIF($C$11:$AA$11,$AM$35)*$AB$11+COUNTIF($C$12:$AA$12,$AM$35)*$AB$12+COUNTIF($C$13:$AA$13,$AM$35)*$AB$13+COUNTIF($C$14:$AA$14,$AM$35)*$AB$14+COUNTIF($C$15:$AA$15,$AM$35)*$AB$15+COUNTIF($C$16:$AA$16,$AM$35)*$AB$16+COUNTIF($C$17:$AA$17,$AM$35)*$AB$17+COUNTIF($C$18:$AA$18,$AM$35)*$AB$18+COUNTIF($C$19:$AA$19,$AM$35)*$AB$19+COUNTIF($C$20:$AA$20,$AM$35)*$AB$20+COUNTIF($C$21:$AA$21,$AM$35)*$AB$21+COUNTIF($C$22:$AA$22,$AM$35)*$AB$22+COUNTIF($C$23:$AA$23,$AM$35)*$AB$23+COUNTIF($C$24:$AA$24,$AM$35)*$AB$24+COUNTIF($C$25:$AA$25,$AM$35)*$AB$25+COUNTIF($C$26:$AA$26,$AM$35)*$AB$26+COUNTIF($C$27:$AA$27,$AM$35)*$AB$27+COUNTIF($C$28:$AA$28,$AM$35)*$AB$28+COUNTIF($C$29:$AA$29,$AM$35)*$AB$29+COUNTIF($C$30:$AA$30,$AM$35)*$AB$30+COUNTIF($C$31:$AA$31,$AM$35)*$AB$31+COUNTIF($C$32:$AA$32,$AM$35)*$AB$32+COUNTIF($C$33:$AA$33,$AM$35)*$AB$33+COUNTIF($C$34:$AA$34,$AM$35)*$AB$34 -> 5 | K8: =COUNTIF($C$4:$AA$4,$AN$35)*$AB$4+COUNTIF($C$5:$AA$5,$AN$35)*$AB$5+COUNTIF($C$6:$AA$6,$AN$35)*$AB$6+COUNTIF($C$7:$AA$7,$AN$35)*$AB$7+COUNTIF($C$8:$AA$8,$AN$35)*$AB$8+COUNTIF($C$9:$AA$9,$AN$35)*$AB$9+COUNTIF($C$10:$AA$10,$AN$35)*$AB$10+COUNTIF($C$11:$AA$11,$AN$35)*$AB$11+COUNTIF($C$12:$AA$12,$AN$35)*$AB$12+COUNTIF($C$13:$AA$13,$AN$35)*$AB$13+COUNTIF($C$14:$AA$14,$AN$35)*$AB$14+COUNTIF($C$15:$AA$15,$AN$35)*$AB$15+COUNTIF($C$16:$AA$16,$AN$35)*$AB$16+COUNTIF($C$17:$AA$17,$AN$35)*$AB$17+COUNTIF($C$18:$AA$18,$AN$35)*$AB$18+COUNTIF($C$19:$AA$19,$AN$35)*$AB$19+COUNTIF($C$20:$AA$20,$AN$35)*$AB$20+COUNTIF($C$21:$AA$21,$AN$35)*$AB$21+COUNTIF($C$22:$AA$22,$AN$35)*$AB$22+COUNTIF($C$23:$AA$23,$AN$35)*$AB$23+COUNTIF($C$24:$AA$24,$AN$35)*$AB$24+COUNTIF($C$25:$AA$25,$AN$35)*$AB$25+COUNTIF($C$26:$AA$26,$AN$35)*$AB$26+COUNTIF($C$27:$AA$27,$AN$35)*$AB$27+COUNTIF($C$28:$AA$28,$AN$35)*$AB$28+COUNTIF($C$29:$AA$29,$AN$35)*$AB$29+COUNTIF($C$30:$AA$30,$AN$35)*$AB$30+COUNTIF($C$31:$AA$31,$AN$35)*$AB$31+COUNTIF($C$32:$AA$32,$AN$35)*$AB$32+COUNTIF($C$33:$AA$33,$AN$35)*$AB$33+COUNTIF($C$34:$AA$34,$AN$35)*$AB$34 -> 12 | L8: =L7*1.25 -> 1.25
A9: Charge aud./mag. | E9: =E7/E3 -> 6 | F9: =F7/F3 -> 7.3015873 | G9: =G7/G3 -> 7 | H9: =H7/H3 -> 4 | I9: =I7/I3 -> 7.25 | J9: =J7/J3 -> 2 | K9: =K7/K3 -> 6.5 | L9: =L7/L3 -> 1
A10: Ch. aud. pond./mag. | B10: =(B8-D8)/B4 -> 5.875 | C10: =C8/C4 -> 2 | E10: =(E8-4)/E4 -> 6.0625 | F10: =(F8-2.75)/F3 -> 7.3015873 | G10: =(G8-4)/G4 -> 7 | H10: =(H8-7.125)/H4 -> 3.65625 | I10: =(I8-3.25)/I4 -> 6 | J10: =J8/J4 -> 2.5 | K10: =(K8-1.25)/K4 -> 5.375 | L10: =L8/L4 -> 1.25
A11: 1/2 jour perm. de semaine | B11: =E11+F11+G11+H11+I11+K11 -> 400 | E11: =25*2*2 -> 100 | F11: =25*2*2 -> 100 | G11: =25*2 -> 50 | H11: =25*2 -> 50 | I11: =25*2 -> 50 | K11: =25*2 -> 50
A12: 1/2 journée perm/mag. | B12: =(B11-9)/B3 -> 10.025641 | C12: =C11/C3 -> 0 | E12: =E11/E3 -> 12.5 | F12: =F11/F3 -> 15.873016 | G12: =G11/G3 -> 8.3333333 | H12: =H11/H3 -> 12.5 | I12: =I11/I3 -> 12.5 | J12: =J11/J3 -> 0 | K12: =K11/K3 -> 25 | L12: =L11/L3 -> 0
A13: total 1/2 journées cabinet | B13: =B5-B8-B11 -> 183.5 | E13: =E5-E8-E11 -> 47.5 | F13: =F5-F8-F11 -> 8.75 | G13: =G5-G8-G11 -> 54 | H13: =H5-H8-H11 -> 28.25 | I13: =I5-I8-I11 -> 22.75 | J13: =J5-J8-J11 -> 45 | K13: =K5-K8-K11 -> -12 | L13: =L5-L8-L11 -> 23.75
A14: 1/2 cab/magistrat | B14: =B13/33 -> 5.5606061 | E14: =E13/E3 -> 5.9375 | F14: =F13/F3 -> 1.3888889 | G14: =G13/G3 -> 9 | H14: =H13/H3 -> 7.0625 | I14: =I13/I3 -> 5.6875 | J14: =J13/J3 -> 22.5 | K14: =K13/K3 -> -6 | L14: =L13/L3 -> 23.75
A15: Jours de cab/mois/mag. | B15: =B14/2 -> 2.780303 | E15: =E14/2 -> 2.96875 | F15: =F14/2 -> 0.69444444 | G15: =G14/2 -> 4.5 | H15: =H14/2 -> 3.53125 | I15: =I14/2 -> 2.84375 | K15: =K14/2 -> -3
A16: Réforme canevas des audiences 2025
B17: Parquet | C17: PR | D17: PRA | E17: PAP | F17: PMF | G17: DEF | H17: COFAC | I17: EP | J17: PCSNE | K17: Pciv | L17: SG
A18: ETPT mag. Parquet | B18: 39 | C18: 1 | D18: 5 | E18: 8 | F18: 6.3 | G18: 6 | H18: 4 | I18: 4 | J18: 2 | K18: 2 | L18: 1
A19: ETPT de perm/audiences | B19: 33 | C19: 1 | E19: 8 | F19: 6 | G19: 6 | H19: 4 | I19: 4 | J19: 2 | K19: 2 | L19: 1
A20: total 1/2 journées (hors Hier.) | B20: =(B18-7)*25 -> 800 | C20: =C18*25 -> 25 | D20: =D18*25 -> 125 | E20: =E18*25 -> 200 | F20: =F18*25 -> 157.5 | G20: =G18*25 -> 150 | H20: =H18*25 -> 100 | I20: =I18*25 -> 100 | J20: =J18*25 -> 50 | ... L20: =L18*25 -> 25
A22: 1/2 j d'audiences (Tcorr, TPE, Tpol, Tcom.) | B22: 156 | C22: =(COUNTIF($C$4:$AA$33,$AF$36)) -> 5 | E22: =(COUNTIF($C$4:$AA$33,$AH$36)) -> 46 | F22: =(COUNTIF($C$4:$AA$33,$AI$36)) -> 57 | G22: =(COUNTIF($C$4:$AA$33,$AJ$36)) -> 42 | H22: =(COUNTIF($C$4:$AA$33,$AK$36)) -> 13 | I22: =(COUNTIF($C$4:$AA$33,$AL$36)) -> 29 | J22: =(COUNTIF($C$4:$AA$33,$AM$36)) -> 4 | K22: =(COUNTIF($C$4:$AA$33,$AN$36)) -> 15 | L22: =(COUNTIF($C$4:$AA$33,"SG")) -> 1
A23: Pondération (jour) | B23: =E23+F23+G23+H23+I23+K23+C23+J23+L23 -> 222.5 | C23: =COUNTIF($C$4:$AA$4,$AF$36)*$AB$4+COUNTIF($C$5:$AA$5,$AF$36)*$AB$5+COUNTIF($C$6:$AA$6,$AF$36)*$AB$6+COUNTIF($C$7:$AA$7,$AF$36)*$AB$7+COUNTIF($C$8:$AA$8,$AF$36)*$AB$8+COUNTIF($C$9:$AA$9,$AF$36)*$AB$9+COUNTIF($C$10:$AA$10,$AF$36)*$AB$10+COUNTIF($C$11:$AA$11,$AF$36)*$AB$11+COUNTIF($C$12:$AA$12,$AF$36)*$AB$12+COUNTIF($C$13:$AA$13,$AF$36)*$AB$13+COUNTIF($C$14:$AA$14,$AF$36)*$AB$14+COUNTIF($C$15:$AA$15,$AF$36)*$AB$15+COUNTIF($C$16:$AA$16,$AF$36)*$AB$16+COUNTIF($C$17:$AA$17,$AF$36)*$AB$17+COUNTIF($C$18:$AA$18,$AF$36)*$AB$18+COUNTIF($C$19:$AA$19,$AF$36)*$AB$19+COUNTIF($C$20:$AA$20,$AF$36)*$AB$20+COUNTIF($C$21:$AA$21,$AF$36)*$AB$21+COUNTIF($C$22:$AA$22,$AF$36)*$AB$22+COUNTIF($C$23:$AA$23,$AF$36)*$AB$23+COUNTIF($C$24:$AA$24,$AF$36)*$AB$24+COUNTIF($C$25:$AA$25,$AF$36)*$AB$25+COUNTIF($C$26:$AA$26,$AF$36)*$AB$26+COUNTIF($C$27:$AA$27,$AF$36)*$AB$27+COUNTIF($C$28:$AA$28,$AF$36)*$AB$28+COUNTIF($C$29:$AA$29,$AF$36)*$AB$29+COUNTIF($C$30:$AA$30,$AF$36)*$AB$30+COUNTIF($C$31:$AA$31,$AF$36)*$AB$31+COUNTIF($C$32:$AA$32,$AF$36)*$AB$32+COUNTIF($C$33:$AA$33,$AF$36)*$AB$33 -> 3 | D23: =4+4+4.25+7.125+3.25 -> 22.625 | E23: =COUNTIF($C$4:$AA$4,$AH$36)*$AB$4+COUNTIF($C$5:$AA$5,$AH$36)*$AB$5+COUNTIF($C$6:$AA$6,$AH$36)*$AB$6+COUNTIF($C$7:$AA$7,$AH$36)*$AB$7+COUNTIF($H$8:$AA$8,$AH$36)*$AB$8+COUNTIF($C$9:$AA$9,$AH$36)*$AB$9+COUNTIF($C$10:$AA$10,$AH$36)*$AB$10+COUNTIF($C$11:$AA$11,$AH$36)*$AB$11+COUNTIF($C$12:$AA$12,$AH$36)*$AB$12+COUNTIF($D$13:$AA$13,$AH$36)*$AB$13+COUNTIF($C$14:$AA$14,$AH$36)*$AB$14+COUNTIF($C$15:$AA$15,$AH$36)*$AB$15+COUNTIF($C$16:$AA$16,$AH$36)*$AB$16+COUNTIF($C$17:$AA$17,$AH$36)*$AB$17+COUNTIF($D$18:$AA$18,$AH$36)*$AB$18+COUNTIF($C$19:$AA$19,$AH$36)*$AB$19+COUNTIF($C$20:$AA$20,$AH$36)*$AB$20+COUNTIF($C$21:$AA$21,$AH$36)*$AB$21+COUNTIF($C$22:$AA$22,$AH$36)*$AB$22+COUNTIF($C$23:$AA$23,$AH$36)*$AB$23+COUNTIF($C$24:$AA$24,$AH$36)*$AB$24+COUNTIF($C$25:$AA$25,$AH$36)*$AB$25+COUNTIF($C$26:$AA$26,$AH$36)*$AB$26+COUNTIF($C$27:$AA$27,$AH$36)*$AB$27+COUNTIF($C$28:$AA$28,$AH$36)*$AB$28+COUNTIF($C$29:$AA$29,$AH$36)*$AB$29+COUNTIF($C$30:$AA$30,$AH$36)*$AB$30+COUNTIF($C$31:$AA$31,$AH$36)*$AB$31+COUNTIF($C$32:$AA$32,$AH$36)*$AB$32+COUNTIF($C$33:$AA$33,$AH$36)*$AB$33 -> 51 | F23: =COUNTIF($C$4:$AA$4,$AI$36)*$AB$4+COUNTIF($C$5:$AA$5,$AI$36)*$AB$5+COUNTIF($C$6:$AA$6,$AI$36)*$AB$6+COUNTIF($C$7:$AA$7,$AI$36)*$AB$7+COUNTIF($H$8:$AA$8,$AI$36)*$AB$8+COUNTIF($C$9:$AA$9,$AI$36)*$AB$9+COUNTIF($C$10:$AA$10,$AI$36)*0.5*$AB$10+COUNTIF($C$11:$AA$11,$AI$36)*$AB$11+COUNTIF($C$12:$AA$12,$AI$36)*$AB$12+COUNTIF($D$13:$AA$13,$AI$36)*$AB$13+COUNTIF($C$14:$AA$14,$AI$36)*$AB$14+COUNTIF($C$15:$AA$15,$AI$36)*$AB$15+COUNTIF($C$16:$AA$16,$AI$36)*$AB$16+COUNTIF($C$17:$AA$17,$AI$36)*$AB$17+COUNTIF($D$18:$AA$18,$AI$36)*$AB$18+COUNTIF($C$19:$AA$19,$AI$36)*$AB$19+COUNTIF($C$20:$AA$20,$AI$36)*$AB$20+COUNTIF($C$21:$AA$21,$AI$36)*$AB$21+COUNTIF($C$22:$AA$22,$AI$36)*$AB$22+COUNTIF($C$23:$AA$23,$AI$36)*$AB$23+COUNTIF($C$24:$AA$24,$AI$36)*$AB$24+COUNTIF($C$25:$AA$25,$AI$36)*$AB$25+COUNTIF($C$26:$AA$26,$AI$36)*$AB$26+COUNTIF($C$27:$AA$27,$AI$36)*$AB$27+COUNTIF($C$28:$AA$28,$AI$36)*$AB$28+COUNTIF($C$29:$AA$29,$AI$36)*$AB$29+COUNTIF($C$30:$AA$30,$AI$36)*$AB$30+COUNTIF($C$31:$AA$31,$AI$36)*$AB$31+COUNTIF($C$32:$AA$32,$AI$36)*$AB$32+COUNTIF($C$33:$AA$33,$AI$36)*$AB$33 -> 56 | G23: =COUNTIF($C$4:$AA$4,$AJ$36)*$AB$4+COUNTIF($C$5:$AA$5,$AJ$36)*$AB$5+COUNTIF($C$6:$AA$6,$AJ$36)*$AB$6+COUNTIF($C$7:$AA$7,$AJ$36)*$AB$7+COUNTIF($H$8:$AA$8,$AJ$36)*$AB$8+COUNTIF($C$9:$AA$9,$AJ$36)*$AB$9+COUNTIF($C$10:$AA$10,$AJ$36)*$AB$10+COUNTIF($C$11:$AA$11,$AJ$36)*$AB$11+COUNTIF($C$12:$AA$12,$AJ$36)*$AB$12+COUNTIF($D$13:$AA$13,$AJ$36)*$AB$13+COUNTIF($C$14:$AA$14,$AJ$36)*$AB$14+COUNTIF($C$15:$AA$15,$AJ$36)*$AB$15+COUNTIF($C$16:$AA$16,$AJ$36)*$AB$16+COUNTIF($C$17:$AA$17,$AJ$36)*$AB$17+COUNTIF($D$18:$AA$18,$AJ$36)*$AB$18+COUNTIF($C$19:$AA$19,$AJ$36)*$AB$19+COUNTIF($C$20:$AA$20,$AJ$36)*$AB$20+COUNTIF($C$21:$AA$21,$AJ$36)*$AB$21+COUNTIF($C$22:$AA$22,$AJ$36)*$AB$22+COUNTIF($C$23:$AA$23,$AJ$36)*$AB$23+COUNTIF($C$24:$AA$24,$AJ$36)*$AB$24+COUNTIF($C$25:$AA$25,$AJ$36)*$AB$25+COUNTIF($C$26:$AA$26,$AJ$36)*$AB$26+COUNTIF($C$27:$AA$27,$AJ$36)*$AB$27+COUNTIF($C$28:$AA$28,$AJ$36)*$AB$28+COUNTIF($C$29:$AA$29,$AJ$36)*$AB$29+COUNTIF($C$30:$AA$30,$AJ$36)*$AB$30+COUNTIF($C$31:$AA$31,$AJ$36)*$AB$31+COUNTIF($C$32:$AA$32,$AJ$36)*$AB$32+COUNTIF($C$33:$AA$33,$AJ$36)*$AB$33 -> 45 | H23: =COUNTIF($C$4:$AA$4,$AK$36)*$AB$4+COUNTIF($C$5:$AA$5,$AK$36)*$AB$5+COUNTIF($C$6:$AA$6,$AK$36)*$AB$6+COUNTIF($C$7:$AA$7,$AK$36)*$AB$7+COUNTIF($H$8:$AA$8,$AK$36)*$AB$8+COUNTIF($C$9:$AA$9,$AK$36)*$AB$9+COUNTIF($C$10:$AA$10,$AK$36)*$AB$10+COUNTIF($C$11:$AA$11,$AK$36)*$AB$11+COUNTIF($C$12:$AA$12,$AK$36)*$AB$12+COUNTIF($D$13:$AA$13,$AK$36)*$AB$13+COUNTIF($C$14:$AA$14,$AK$36)*$AB$14+COUNTIF($C$15:$AA$15,$AK$36)*$AB$15+COUNTIF($C$16:$AA$16,$AK$36)*$AB$16+COUNTIF($C$17:$AA$17,$AK$36)*$AB$17+COUNTIF($D$18:$AA$18,$AK$36)*$AB$18+COUNTIF($C$19:$AA$19,$AK$36)*$AB$19+COUNTIF($C$20:$AA$20,$AK$36)*$AB$20+COUNTIF($C$21:$AA$21,$AK$36)*$AB$21+COUNTIF($C$22:$AA$22,$AK$36)*$AB$22+COUNTIF($C$23:$AA$23,$AK$36)*$AB$23+COUNTIF($C$24:$AA$24,$AK$36)*$AB$24+COUNTIF($C$25:$AA$25,$AK$36)*$AB$25+COUNTIF($C$26:$AA$26,$AK$36)*$AB$26+COUNTIF($C$27:$AA$27,$AK$36)*$AB$27+COUNTIF($C$28:$AA$28,$AK$36)*$AB$28+COUNTIF($C$29:$AA$29,$AK$36)*$AB$29+COUNTIF($C$30:$AA$30,$AK$36)*$AB$30+COUNTIF($C$31:$AA$31,$AK$36)*$AB$31+COUNTIF($C$32:$AA$32,$AK$36)*$AB$32+COUNTIF($C$33:$AA$33,$AK$36)*$AB$33 -> 19.25 | I23: =COUNTIF($C$4:$AA$4,$AL$36)*$AB$4+COUNTIF($C$5:$AA$5,$AL$36)*$AB$5+COUNTIF($C$6:$AA$6,$AL$36)*$AB$6+COUNTIF($C$7:$AA$7,$AL$36)*$AB$7+COUNTIF($H$8:$AA$8,$AL$36)*$AB$8+COUNTIF($C$9:$AA$9,$AL$36)*$AB$9+COUNTIF($C$10:$AA$10,$AL$36)*$AB$10+COUNTIF($C$11:$AA$11,$AL$36)*$AB$11+COUNTIF($C$12:$AA$12,$AL$36)*$AB$12+COUNTIF($D$13:$AA$13,$AL$36)*$AB$13+COUNTIF($C$14:$AA$14,$AL$36)*$AB$14+COUNTIF($C$15:$AA$15,$AL$36)*$AB$15+COUNTIF($C$16:$AA$16,$AL$36)*$AB$16+COUNTIF($C$17:$AA$17,$AL$36)*$AB$17+COUNTIF($D$18:$AA$18,$AL$36)*$AB$18+COUNTIF($C$19:$AA$19,$AL$36)*$AB$19+COUNTIF($C$20:$AA$20,$AL$36)*$AB$20+COUNTIF($C$21:$AA$21,$AL$36)*$AB$21+COUNTIF($C$22:$AA$22,$AL$36)*$AB$22+COUNTIF($C$23:$AA$23,$AL$36)*$AB$23+COUNTIF($C$24:$AA$24,$AL$36)*$AB$24+COUNTIF($C$25:$AA$25,$AL$36)*$AB$25+COUNTIF($C$26:$AA$26,$AL$36)*$AB$26+COUNTIF($C$27:$AA$27,$AL$36)*$AB$27+COUNTIF($C$28:$AA$28,$AL$36)*$AB$28+COUNTIF($C$29:$AA$29,$AL$36)*$AB$29+COUNTIF($C$30:$AA$30,$AL$36)*$AB$30+COUNTIF($C$31:$AA$31,$AL$36)*$AB$31+COUNTIF($C$32:$AA$32,$AL$36)*$AB$32+COUNTIF($C$33:$AA$33,$AL$36)*$AB$33 -> 27.25 | J23: =COUNTIF($C$4:$AA$4,$AM$36)*$AB$4+COUNTIF($C$5:$AA$5,$AM$36)*$AB$5+COUNTIF($C$6:$AA$6,$AM$36)*$AB$6+COUNTIF($C$7:$AA$7,$AM$36)*$AB$7+COUNTIF($H$8:$AA$8,$AM$36)*$AB$8+COUNTIF($C$9:$AA$9,$AM$36)*$AB$9+COUNTIF($C$10:$AA$10,$AM$36)*$AB$10+COUNTIF($C$11:$AA$11,$AM$36)*$AB$11+COUNTIF($C$12:$AA$12,$AM$36)*$AB$12+COUNTIF($D$13:$AA$13,$AM$36)*$AB$13+COUNTIF($C$14:$AA$14,$AM$36)*$AB$14+COUNTIF($C$15:$AA$15,$AM$36)*$AB$15+COUNTIF($C$16:$AA$16,$AM$36)*$AB$16+COUNTIF($C$17:$AA$17,$AM$36)*$AB$17+COUNTIF($D$18:$AA$18,$AM$36)*$AB$18+COUNTIF($C$19:$AA$19,$AM$36)*$AB$19+COUNTIF($C$20:$AA$20,$AM$36)*$AB$20+COUNTIF($C$21:$AA$21,$AM$36)*$AB$21+COUNTIF($C$22:$AA$22,$AM$36)*$AB$22+COUNTIF($C$23:$AA$23,$AM$36)*$AB$23+COUNTIF($C$24:$AA$24,$AM$36)*$AB$24+COUNTIF($C$25:$AA$25,$AM$36)*$AB$25+COUNTIF($C$26:$AA$26,$AM$36)*$AB$26+COUNTIF($C$27:$AA$27,$AM$36)*$AB$27+COUNTIF($C$28:$AA$28,$AM$36)*$AB$28+COUNTIF($C$29:$AA$29,$AM$36)*$AB$29+COUNTIF($C$30:$AA$30,$AM$36)*$AB$30+COUNTIF($C$31:$AA$31,$AM$36)*$AB$31+COUNTIF($C$32:$AA$32,$AM$36)*$AB$32+COUNTIF($C$33:$AA$33,$AM$36)*$AB$33 -> 5 | K23: =COUNTIF($C$4:$AA$4,$AN$36)*$AB$4+COUNTIF($C$5:$AA$5,$AN$36)*$AB$5+COUNTIF($C$6:$AA$6,$AN$36)*$AB$6+COUNTIF($C$7:$AA$7,$AN$36)*$AB$7+COUNTIF($H$8:$AA$8,$AN$36)*$AB$8+COUNTIF($C$9:$AA$9,$AN$36)*$AB$9+COUNTIF($C$10:$AA$10,$AN$36)*$AB$10+COUNTIF($C$11:$AA$11,$AN$36)*$AB$11+COUNTIF($C$12:$AA$12,$AN$36)*$AB$12+COUNTIF($D$13:$AA$13,$AN$36)*$AB$13+COUNTIF($C$14:$AA$14,$AN$36)*$AB$14+COUNTIF($C$15:$AA$15,$AN$36)*$AB$15+COUNTIF($C$16:$AA$16,$AN$36)*$AB$16+COUNTIF($C$17:$AA$17,$AN$36)*$AB$17+COUNTIF($D$18:$AA$18,$AN$36)*$AB$18+COUNTIF($C$19:$AA$19,$AN$36)*$AB$19+COUNTIF($C$20:$AA$20,$AN$36)*$AB$20+COUNTIF($C$21:$AA$21,$AN$36)*$AB$21+COUNTIF($C$22:$AA$22,$AN$36)*$AB$22+COUNTIF($C$23:$AA$23,$AN$36)*$AB$23+COUNTIF($C$24:$AA$24,$AN$36)*$AB$24+COUNTIF($C$25:$AA$25,$AN$36)*$AB$25+COUNTIF($C$26:$AA$26,$AN$36)*$AB$26+COUNTIF($C$27:$AA$27,$AN$36)*$AB$27+COUNTIF($C$28:$AA$28,$AN$36)*$AB$28+COUNTIF($C$29:$AA$29,$AN$36)*$AB$29+COUNTIF($C$30:$AA$30,$AN$36)*$AB$30+COUNTIF($C$31:$AA$31,$AN$36)*$AB$31+COUNTIF($C$32:$AA$32,$AN$36)*$AB$32+COUNTIF($C$33:$AA$33,$AN$36)*$AB$33 -> 14.75 | L23: =L22*1.25 -> 1.25
A24: Charge aud./mag. | E24: =E22/E18 -> 5.75 | F24: =F22/F18 -> 9.047619 | G24: =G22/G18 -> 7 | H24: =H22/H18 -> 3.25 | I24: =I22/I18 -> 7.25 | J24: =J22/J18 -> 2 | K24: =K22/K18 -> 7.5 | L24: =L22/L18 -> 1
A25: Ch. aud. pond./mag. | B25: =(B23-D23)/B19 -> 6.0568182 | C25: =C23/C19 -> 3 | E25: =(E23-4)/E19 -> 5.875 | F25: =(F23-2.75)/F18 -> 8.452381 | G25: =(G23-4)/G19 -> 6.8333333 | H25: =(H23-7.125)/H19 -> 3.03125 | I25: =(I23-3.25)/I19 -> 6 | J25: =J23/J19 -> 2.5 | K25: =(K23-1.25)/K19 -> 6.75 | L25: =L23/L19 -> 1.25
A26: 1/2 jour perm. de semaine | B26: =E26+F26+G26+H26+I26+K26 -> 400 | E26: =25*2*2 -> 100 | F26: =25*2*2 -> 100 | G26: =25*2 -> 50 | H26: =25*2 -> 50 | I26: =25*2 -> 50 | K26: =25*2 -> 50
A27: 1/2 journée perm/mag. | B27: =(B26-9)/B18 -> 10.025641 | C27: =C26/C18 -> 0 | E27: =E26/E18 -> 12.5 | F27: =F26/F18 -> 15.873016 | G27: =G26/G18 -> 8.3333333 | H27: =H26/H18 -> 12.5 | I27: =I26/I18 -> 12.5 | J27: =J26/J18 -> 0 | K27: =K26/K18 -> 25 | L27: =L26/L18 -> 0
A28: total 1/2 journées cabinet | B28: =B20-B23-B26 -> 177.5 | E28: =E20-E23-E26 -> 49 | F28: =F20-F23-F26 -> 1.5 | G28: =G20-G23-G26 -> 55 | H28: =H20-H23-H26 -> 30.75 | I28: =I20-I23-I26 -> 22.75 | J28: =J20-J23-J26 -> 45 | K28: =K20-K23-K26 -> -14.75 | L28: =L20-L23-L26 -> 23.75
A29: 1/2 cab/magistrat | B29: =B28/33 -> 5.3787879 | E29: =E28/E18 -> 6.125 | F29: =F28/F18 -> 0.23809524 | G29: =G28/G18 -> 9.1666667 | H29: =H28/H18 -> 7.6875 | I29: =I28/I18 -> 5.6875 | J29: =J28/J18 -> 22.5 | K29: =K28/K18 -> -7.375 | L29: =L28/L18 -> 23.75
A30: Jours de cab/mois/mag. | B30: =B29/2 -> 2.6893939 | E30: =E29/2 -> 3.0625 | F30: =F29/2 -> 0.11904762 | G30: =G29/2 -> 4.5833333 | H30: =H29/2 -> 3.84375 | I30: =I29/2 -> 2.84375 | K30: =K29/2 -> -3.6875
A32: Proposition de rééquilibrage 2025
B33: Parquet | C33: PR | D33: PRA | E33: A | F33: M | G33: E | H33: S | I33: P | J33: N | K33: C | L33: SG
A34: ETPT mag. Parquet | B34: 39 | C34: 1 | D34: 5 | E34: 8 | F34: 6.3 | G34: 6 | H34: 4 | I34: 4 | J34: 2 | K34: 2 | L34: 1
A35: ETPT de perm/audiences | B35: 33 | C35: 1 | E35: 8 | F35: 6 | G35: 6 | H35: 4 | I35: 4 | J35: 2 | K35: 2 | L35: 1
A36: total 1/2 journées (hors Hier.) | B36: =(B34-7)*25 -> 800 | C36: =C34*25 -> 25 | D36: =D34*25 -> 125 | E36: =E34*25 -> 200 | F36: =F34*25 -> 157.5 | G36: =G34*25 -> 150 | H36: =H34*25 -> 100 | I36: =I34*25 -> 100 | J36: =J34*25 -> 50 | ... L36: =L34*25 -> 25
A38: 1/2 j d'audiences (Tcorr, TPE, Tpol, Tcom.) | B38: 156 | C38: =(COUNTIF($C$4:$AA$33,$AF$36)) -> 5 | E38: =(COUNTIF($C$4:$AA$33,$AH$36)) -> 52 | F38: =(COUNTIF($C$4:$AA$33,$AI$36)) -> 46 | G38: =(COUNTIF($C$4:$AA$33,$AJ$36)) -> 41 | H38: =(COUNTIF($C$4:$AA$33,"S")) -> 18 | I38: =(COUNTIF($C$4:$AA$33,"P")) -> 30 | J38: =(COUNTIF($C$4:$AA$33,"N")) -> 4 | K38: =(COUNTIF($C$4:$AA$33,"C")) -> 15 | L38: =(COUNTIF($C$4:$AA$33,"SG")) -> 1
A39: Pondération (jour) | B39: =E39+F39+G39+H39+I39+K39+C39+J39+L39 -> 222.5 | C39: =COUNTIF($C$4:$AA$4,$AF$36)*$AB$4+COUNTIF($C$5:$AA$5,$AF$36)*$AB$5+COUNTIF($C$6:$AA$6,$AF$36)*$AB$6+COUNTIF($C$7:$AA$7,$AF$36)*$AB$7+COUNTIF($C$8:$AA$8,$AF$36)*$AB$8+COUNTIF($C$9:$AA$9,$AF$36)*$AB$9+COUNTIF($C$10:$AA$10,$AF$36)*$AB$10+COUNTIF($C$11:$AA$11,$AF$36)*$AB$11+COUNTIF($C$12:$AA$12,$AF$36)*$AB$12+COUNTIF($C$13:$AA$13,$AF$36)*$AB$13+COUNTIF($C$14:$AA$14,$AF$36)*$AB$14+COUNTIF($C$15:$AA$15,$AF$36)*$AB$15+COUNTIF($C$16:$AA$16,$AF$36)*$AB$16+COUNTIF($C$17:$AA$17,$AF$36)*$AB$17+COUNTIF($C$18:$AA$18,$AF$36)*$AB$18+COUNTIF($C$19:$AA$19,$AF$36)*$AB$19+COUNTIF($C$20:$AA$20,$AF$36)*$AB$20+COUNTIF($C$21:$AA$21,$AF$36)*$AB$21+COUNTIF($C$22:$AA$22,$AF$36)*$AB$22+COUNTIF($C$23:$AA$23,$AF$36)*$AB$23+COUNTIF($C$24:$AA$24,$AF$36)*$AB$24+COUNTIF($C$25:$AA$25,$AF$36)*$AB$25+COUNTIF($C$26:$AA$26,$AF$36)*$AB$26+COUNTIF($C$27:$AA$27,$AF$36)*$AB$27+COUNTIF($C$28:$AA$28,$AF$36)*$AB$28+COUNTIF($C$29:$AA$29,$AF$36)*$AB$29+COUNTIF($C$30:$AA$30,$AF$36)*$AB$30+COUNTIF($C$31:$AA$31,$AF$36)*$AB$31+COUNTIF($C$32:$AA$32,$AF$36)*$AB$32+COUNTIF($C$33:$AA$33,$AF$36)*$AB$33 -> 3 | D39: =4+4+4.25+7.125+3.25 -> 22.625 | E39: =COUNTIF($C$4:$AA$4,$AH$36)*$AB$4+COUNTIF($C$5:$AA$5,$AH$36)*$AB$5+COUNTIF($C$6:$AA$6,$AH$36)*$AB$6+COUNTIF($C$7:$AA$7,$AH$36)*$AB$7+COUNTIF($C$8:$AA$8,$AH$36)*$AB$8+COUNTIF($C$9:$AA$9,$AH$36)*$AB$9+COUNTIF($C$10:$AA$10,$AH$36)*$AB$10+COUNTIF($C$11:$AA$11,$AH$36)*$AB$11+COUNTIF($C$12:$AA$12,$AH$36)*$AB$12+COUNTIF($C$13:$AA$13,$AH$36)*$AB$13+COUNTIF($C$14:$AA$14,$AH$36)*$AB$14+COUNTIF($C$15:$AA$15,$AH$36)*$AB$15+COUNTIF($C$16:$AA$16,$AH$36)*$AB$16+COUNTIF($C$17:$AA$17,$AH$36)*$AB$17+COUNTIF($C$18:$AA$18,$AH$36)*$AB$18+COUNTIF($C$19:$AA$19,$AH$36)*$AB$19+COUNTIF($C$20:$AA$20,$AH$36)*$AB$20+COUNTIF($C$21:$AA$21,$AH$36)*$AB$21+COUNTIF($C$22:$AA$22,$AH$36)*$AB$22+COUNTIF($C$23:$AA$23,$AH$36)*$AB$23+COUNTIF($C$24:$AA$24,$AH$36)*$AB$24+COUNTIF($C$25:$AA$25,$AH$36)*$AB$25+COUNTIF($C$26:$AA$26,$AH$36)*$AB$26+COUNTIF($C$27:$AA$27,$AH$36)*$AB$27+COUNTIF($C$28:$AA$28,$AH$36)*$AB$28+COUNTIF($C$29:$AA$29,$AH$36)*$AB$29+COUNTIF($C$30:$AA$30,$AH$36)*$AB$30+COUNTIF($C$31:$AA$31,$AH$36)*$AB$31+COUNTIF($C$32:$AA$32,$AH$36)*$AB$32+COUNTIF($C$33:$AA$33,$AH$36)*$AB$33 -> 57.25 | F39: =COUNTIF($C$4:$AA$4,$AI$36)*$AB$4+COUNTIF($C$5:$AA$5,$AI$36)*$AB$5+COUNTIF($C$6:$AA$6,$AI$36)*$AB$6+COUNTIF($C$7:$AA$7,$AI$36)*$AB$7+COUNTIF($H$8:$AA$8,$AI$36)*$AB$8+COUNTIF($C$9:$AA$9,$AI$36)*$AB$9+COUNTIF($C$10:$AA$10,$AI$36)*0.5*$AB$10+COUNTIF($C$11:$AA$11,$AI$36)*$AB$11+COUNTIF($C$12:$AA$12,$AI$36)*$AB$12+COUNTIF($D$13:$AA$13,$AI$36)*$AB$13+COUNTIF($C$14:$AA$14,$AI$36)*$AB$14+COUNTIF($C$15:$AA$15,$AI$36)*$AB$15+COUNTIF($C$16:$AA$16,$AI$36)*$AB$16+COUNTIF($C$17:$AA$17,$AI$36)*$AB$17+COUNTIF($D$18:$AA$18,$AI$36)*$AB$18+COUNTIF($C$19:$AA$19,$AI$36)*$AB$19+COUNTIF($C$20:$AA$20,$AI$36)*$AB$20+COUNTIF($C$21:$AA$21,$AI$36)*$AB$21+COUNTIF($C$22:$AA$22,$AI$36)*$AB$22+COUNTIF($C$23:$AA$23,$AI$36)*$AB$23+COUNTIF($C$24:$AA$24,$AI$36)*$AB$24+COUNTIF($C$25:$AA$25,$AI$36)*$AB$25+COUNTIF($C$26:$AA$26,$AI$36)*$AB$26+COUNTIF($C$27:$AA$27,$AI$36)*$AB$27+COUNTIF($C$28:$AA$28,$AI$36)*$AB$28+COUNTIF($C$29:$AA$29,$AI$36)*$AB$29+COUNTIF($C$30:$AA$30,$AI$36)*$AB$30+COUNTIF($C$31:$AA$31,$AI$36)*$AB$31+COUNTIF($C$32:$AA$32,$AI$36)*$AB$32+COUNTIF($C$33:$AA$33,$AI$36)*$AB$33 -> 45 | G39: =COUNTIF($C$4:$AA$4,$AJ$36)*$AB$4+COUNTIF($C$5:$AA$5,$AJ$36)*$AB$5+COUNTIF($C$6:$AA$6,$AJ$36)*$AB$6+COUNTIF($C$7:$AA$7,$AJ$36)*$AB$7+COUNTIF($H$8:$AA$8,$AJ$36)*$AB$8+COUNTIF($C$9:$AA$9,$AJ$36)*$AB$9+COUNTIF($C$10:$AA$10,$AJ$36)*$AB$10+COUNTIF($C$11:$AA$11,$AJ$36)*$AB$11+COUNTIF($C$12:$AA$12,$AJ$36)*$AB$12+COUNTIF($D$13:$AA$13,$AJ$36)*$AB$13+COUNTIF($C$14:$AA$14,$AJ$36)*$AB$14+COUNTIF($C$15:$AA$15,$AJ$36)*$AB$15+COUNTIF($C$16:$AA$16,$AJ$36)*$AB$16+COUNTIF($C$17:$AA$17,$AJ$36)*$AB$17+COUNTIF($D$18:$AA$18,$AJ$36)*$AB$18+COUNTIF($C$19:$AA$19,$AJ$36)*$AB$19+COUNTIF($C$20:$AA$20,$AJ$36)*$AB$20+COUNTIF($C$21:$AA$21,$AJ$36)*$AB$21+COUNTIF($C$22:$AA$22,$AJ$36)*$AB$22+COUNTIF($C$23:$AA$23,$AJ$36)*$AB$23+COUNTIF($C$24:$AA$24,$AJ$36)*$AB$24+COUNTIF($C$25:$AA$25,$AJ$36)*$AB$25+COUNTIF($C$26:$AA$26,$AJ$36)*$AB$26+COUNTIF($C$27:$AA$27,$AJ$36)*$AB$27+COUNTIF($C$28:$AA$28,$AJ$36)*$AB$28+COUNTIF($C$29:$AA$29,$AJ$36)*$AB$29+COUNTIF($C$30:$AA$30,$AJ$36)*$AB$30+COUNTIF($C$31:$AA$31,$AJ$36)*$AB$31+COUNTIF($C$32:$AA$32,$AJ$36)*$AB$32+COUNTIF($C$33:$AA$33,$AJ$36)*$AB$33 -> 44 | H39: =COUNTIF($C$4:$AA$4,$AK$36)*$AB$4+COUNTIF($C$5:$AA$5,$AK$36)*$AB$5+COUNTIF($C$6:$AA$6,$AK$36)*$AB$6+COUNTIF($C$7:$AA$7,$AK$36)*$AB$7+COUNTIF($H$8:$AA$8,$AK$36)*$AB$8+COUNTIF($C$9:$AA$9,$AK$36)*$AB$9+COUNTIF($C$10:$AA$10,$AK$36)*$AB$10+COUNTIF($C$11:$AA$11,$AK$36)*$AB$11+COUNTIF($C$12:$AA$12,$AK$36)*$AB$12+COUNTIF($D$13:$AA$13,$AK$36)*$AB$13+COUNTIF($C$14:$AA$14,$AK$36)*$AB$14+COUNTIF($C$15:$AA$15,$AK$36)*$AB$15+COUNTIF($C$16:$AA$16,$AK$36)*$AB$16+COUNTIF($C$17:$AA$17,$AK$36)*$AB$17+COUNTIF($D$18:$AA$18,$AK$36)*$AB$18+COUNTIF($C$19:$AA$19,$AK$36)*$AB$19+COUNTIF($C$20:$AA$20,$AK$36)*$AB$20+COUNTIF($C$21:$AA$21,$AK$36)*$AB$21+COUNTIF($C$22:$AA$22,$AK$36)*$AB$22+COUNTIF($C$23:$AA$23,$AK$36)*$AB$23+COUNTIF($C$24:$AA$24,$AK$36)*$AB$24+COUNTIF($C$25:$AA$25,$AK$36)*$AB$25+COUNTIF($C$26:$AA$26,$AK$36)*$AB$26+COUNTIF($C$27:$AA$27,$AK$36)*$AB$27+COUNTIF($C$28:$AA$28,$AK$36)*$AB$28+COUNTIF($C$29:$AA$29,$AK$36)*$AB$29+COUNTIF($C$30:$AA$30,$AK$36)*$AB$30+COUNTIF($C$31:$AA$31,$AK$36)*$AB$31+COUNTIF($C$32:$AA$32,$AK$36)*$AB$32+COUNTIF($C$33:$AA$33,$AK$36)*$AB$33 -> 24.5 | I39: =COUNTIF($C$4:$AA$4,$AL$36)*$AB$4+COUNTIF($C$5:$AA$5,$AL$36)*$AB$5+COUNTIF($C$6:$AA$6,$AL$36)*$AB$6+COUNTIF($C$7:$AA$7,$AL$36)*$AB$7+COUNTIF($H$8:$AA$8,$AL$36)*$AB$8+COUNTIF($C$9:$AA$9,$AL$36)*$AB$9+COUNTIF($C$10:$AA$10,$AL$36)*$AB$10+COUNTIF($C$11:$AA$11,$AL$36)*$AB$11+COUNTIF($C$12:$AA$12,$AL$36)*$AB$12+COUNTIF($D$13:$AA$13,$AL$36)*$AB$13+COUNTIF($C$14:$AA$14,$AL$36)*$AB$14+COUNTIF($C$15:$AA$15,$AL$36)*$AB$15+COUNTIF($C$16:$AA$16,$AL$36)*$AB$16+COUNTIF($C$17:$AA$17,$AL$36)*$AB$17+COUNTIF($D$18:$AA$18,$AL$36)*$AB$18+COUNTIF($C$19:$AA$19,$AL$36)*$AB$19+COUNTIF($C$20:$AA$20,$AL$36)*$AB$20+COUNTIF($C$21:$AA$21,$AL$36)*$AB$21+COUNTIF($C$22:$AA$22,$AL$36)*$AB$22+COUNTIF($C$23:$AA$23,$AL$36)*$AB$23+COUNTIF($C$24:$AA$24,$AL$36)*$AB$24+COUNTIF($C$25:$AA$25,$AL$36)*$AB$25+COUNTIF($C$26:$AA$26,$AL$36)*$AB$26+COUNTIF($C$27:$AA$27,$AL$36)*$AB$27+COUNTIF($C$28:$AA$28,$AL$36)*$AB$28+COUNTIF($C$29:$AA$29,$AL$36)*$AB$29+COUNTIF($C$30:$AA$30,$AL$36)*$AB$30+COUNTIF($C$31:$AA$31,$AL$36)*$AB$31+COUNTIF($C$32:$AA$32,$AL$36)*$AB$32+COUNTIF($C$33:$AA$33,$AL$36)*$AB$33 -> 28.25 | J39: =COUNTIF($C$4:$AA$4,$AM$36)*$AB$4+COUNTIF($C$5:$AA$5,$AM$36)*$AB$5+COUNTIF($C$6:$AA$6,$AM$36)*$AB$6+COUNTIF($C$7:$AA$7,$AM$36)*$AB$7+COUNTIF($H$8:$AA$8,$AM$36)*$AB$8+COUNTIF($C$9:$AA$9,$AM$36)*$AB$9+COUNTIF($C$10:$AA$10,$AM$36)*$AB$10+COUNTIF($C$11:$AA$11,$AM$36)*$AB$11+COUNTIF($C$12:$AA$12,$AM$36)*$AB$12+COUNTIF($D$13:$AA$13,$AM$36)*$AB$13+COUNTIF($C$14:$AA$14,$AM$36)*$AB$14+COUNTIF($C$15:$AA$15,$AM$36)*$AB$15+COUNTIF($C$16:$AA$16,$AM$36)*$AB$16+COUNTIF($C$17:$AA$17,$AM$36)*$AB$17+COUNTIF($D$18:$AA$18,$AM$36)*$AB$18+COUNTIF($C$19:$AA$19,$AM$36)*$AB$19+COUNTIF($C$20:$AA$20,$AM$36)*$AB$20+COUNTIF($C$21:$AA$21,$AM$36)*$AB$21+COUNTIF($C$22:$AA$22,$AM$36)*$AB$22+COUNTIF($C$23:$AA$23,$AM$36)*$AB$23+COUNTIF($C$24:$AA$24,$AM$36)*$AB$24+COUNTIF($C$25:$AA$25,$AM$36)*$AB$25+COUNTIF($C$26:$AA$26,$AM$36)*$AB$26+COUNTIF($C$27:$AA$27,$AM$36)*$AB$27+COUNTIF($C$28:$AA$28,$AM$36)*$AB$28+COUNTIF($C$29:$AA$29,$AM$36)*$AB$29+COUNTIF($C$30:$AA$30,$AM$36)*$AB$30+COUNTIF($C$31:$AA$31,$AM$36)*$AB$31+COUNTIF($C$32:$AA$32,$AM$36)*$AB$32+COUNTIF($C$33:$AA$33,$AM$36)*$AB$33 -> 5 | K39: =COUNTIF($C$4:$AA$4,$AN$36)*$AB$4+COUNTIF($C$5:$AA$5,$AN$36)*$AB$5+COUNTIF($C$6:$AA$6,$AN$36)*$AB$6+COUNTIF($C$7:$AA$7,$AN$36)*$AB$7+COUNTIF($H$8:$AA$8,$AN$36)*$AB$8+COUNTIF($C$9:$AA$9,$AN$36)*$AB$9+COUNTIF($C$10:$AA$10,$AN$36)*$AB$10+COUNTIF($C$11:$AA$11,$AN$36)*$AB$11+COUNTIF($C$12:$AA$12,$AN$36)*$AB$12+COUNTIF($D$13:$AA$13,$AN$36)*$AB$13+COUNTIF($C$14:$AA$14,$AN$36)*$AB$14+COUNTIF($C$15:$AA$15,$AN$36)*$AB$15+COUNTIF($C$16:$AA$16,$AN$36)*$AB$16+COUNTIF($C$17:$AA$17,$AN$36)*$AB$17+COUNTIF($D$18:$AA$18,$AN$36)*$AB$18+COUNTIF($C$19:$AA$19,$AN$36)*$AB$19+COUNTIF($C$20:$AA$20,$AN$36)*$AB$20+COUNTIF($C$21:$AA$21,$AN$36)*$AB$21+COUNTIF($C$22:$AA$22,$AN$36)*$AB$22+COUNTIF($C$23:$AA$23,$AN$36)*$AB$23+COUNTIF($C$24:$AA$24,$AN$36)*$AB$24+COUNTIF($C$25:$AA$25,$AN$36)*$AB$25+COUNTIF($C$26:$AA$26,$AN$36)*$AB$26+COUNTIF($C$27:$AA$27,$AN$36)*$AB$27+COUNTIF($C$28:$AA$28,$AN$36)*$AB$28+COUNTIF($C$29:$AA$29,$AN$36)*$AB$29+COUNTIF($C$30:$AA$30,$AN$36)*$AB$30+COUNTIF($C$31:$AA$31,$AN$36)*$AB$31+COUNTIF($C$32:$AA$32,$AN$36)*$AB$32+COUNTIF($C$33:$AA$33,$AN$36)*$AB$33 -> 14.25 | L39: =L38*1.25 -> 1.25
A40: Charge aud./mag. | E40: =E38/E34 -> 6.5 | F40: =F38/F34 -> 7.3015873 | G40: =G38/G34 -> 6.8333333 | H40: =H38/H34 -> 4.5 | I40: =I38/I34 -> 7.5 | J40: =J38/J34 -> 2 | K40: =K38/K34 -> 7.5 | L40: =L38/L34 -> 1
A41: Ch. aud. pond./mag. | B41: =(B39-D39)/B35 -> 6.0568182 | C41: =C39/C35 -> 3 | E41: =(E39-4)/E35 -> 6.65625 | F41: =(F39-2.75)/F34 -> 6.7063492 | G41: =(G39-4)/G35 -> 6.6666667 | H41: =(H39-7.125)/H35 -> 4.34375 | I41: =(I39-3.25)/I35 -> 6.25 | J41: =J39/J35 -> 2.5 | K41: =(K39-1.25)/K35 -> 6.5 | L41: =L39/L35 -> 1.25
A42: 1/2 jour perm. de semaine | B42: =E42+F42+G42+H42+I42+K42 -> 400 | E42: =25*2*2 -> 100 | F42: =25*2*2 -> 100 | G42: =25*2 -> 50 | H42: =25*2 -> 50 | I42: =25*2 -> 50 | K42: =25*2 -> 50
A43: 1/2 journée perm/mag. | B43: =(B42-9)/B34 -> 10.025641 | C43: =C42/C34 -> 0 | E43: =E42/E34 -> 12.5 | F43: =F42/F34 -> 15.873016 | G43: =G42/G34 -> 8.3333333 | H43: =H42/H34 -> 12.5 | I43: =I42/I34 -> 12.5 | J43: =J42/J34 -> 0 | K43: =K42/K34 -> 25 | L43: =L42/L34 -> 0
A44: total 1/2 journées cabinet | B44: =B36-B39-B42 -> 177.5 | E44: =E36-E39-E42 -> 42.75 | F44: =F36-F39-F42 -> 12.5 | G44: =G36-G39-G42 -> 56 | H44: =H36-H39-H42 -> 25.5 | I44: =I36-I39-I42 -> 21.75 | J44: =J36-J39-J42 -> 45 | K44: =K36-K39-K42 -> -14.25 | L44: =L36-L39-L42 -> 23.75
...

Sheet Actuel
B1: Tableau de répartition des audiences entre les divisions du parquet (mars 2024) | AG1: PR | AH1: PRA | AI1: PAP | AJ1: PMF | AK1: V | AL1: DEF | AM1: COFAC | AN1: J | AO1: EP | AP1: PCC | AQ1: Civil | AR1: SG
E2: LUNDI | J2: MARDI | O2: MERCREDI | T2: JEUDI | Y2: VENDREDI | AB2: Pond. | AF2: Parquet | AG2: PR | AH2: PRA | AI2: A | AJ2: M | AK2: V. Deneux | AL2: E | AM2: S | AN2: JPO | AO2: P | AP2: N | AQ2: C | AR2: SG
C3: 1 | D3: 2 | E3: 3 | F3: 4 | G3: 5 | H3: 1 | I3: 2 | J3: 3 | K3: 4 | L3: 5 | M3: 1 | N3: 2 | O3: 3 | P3: 4 | Q3: 5 | R3: 1 | S3: 2 | T3: 3 | U3: 4 | V3: 5 | W3: 1 | X3: 2 | Y3: 3 | Z3: 4 | AA3: 5 | AE3: ETPT mag. Parquet | AF3: 39 | AG3: 1 | AH3: 5 | AI3: 8 | AJ3: 7 | AK3: 1 | AL3: 6 | AM3: 4 | AN3: 1 | AO3: 4 | AP3: 2 | AQ3: 2 | AR3: 1
A4: 9h | B4: 11 JU | C4: A | D4: A | F4: A | G4: A | H4: A | I4: A | J4: A | K4: A | L4: A | AB4: =1 -> 1 | AE4: ETPT de perm/audiences | AF4: 33 | AG4: 1 | AI4: 8 | AJ4: 7 | AK4: =(COUNTIF($C$4:$AA$33,$AJ$23)) -> 0 | AL4: 6 | AM4: 4 | AN4: 1 | AO4: 4 | AP4: 2 | AQ4: 2 | AR4: 1
A5: 9h | B5: 12 JU | W5: A | Y5: A | Z5: A | AA5: A | AB5: 1 | AE5: total 1/2 journées (hors Hier.) | AF5: =(AF3-7)*25 -> 800 | AG5: =AG3*25 -> 25 | AH5: =AH3*25 -> 125 | AI5: =AI3*25 -> 200 | AJ5: =AJ3*25 -> 175 | AK5: =(COUNTIF($C$22:$AA$33,AK1))+(COUNTIF($C$13:$AA$13,AK1))+(COUNTIF($C$4:$AA$11,AK1)) -> 0 | AL5: =AL3*25 -> 150 | AM5: =AM3*25 -> 100 | AO5: =AO3*25 -> 100 | AP5: =AP3*25 -> 50 | AQ5: =AQ3*25 -> 50 | AR5: =AR3*25 -> 25
A6: 9h | B6: 13 JU | C6: M | D6: M | E6: M | F6: M | G6: M | AB6: 1
A7: 9h | B7: 17 JU | M7: A | N7: A | O7: A | P7: A | Q7: A | W7: E | X7: A | Y7: E | Z7: C | AA7: M | AB7: 1 | AE7: 1/2 j d'audiences (Tcorr, TPE, Tpol, Tcom.) | AF7: =SUM(AG7:AR7) -> 207 | AG7: =(COUNTIF($C$4:$AA$33,$AG$2)) -> 4 | AI7: =(COUNTIF($C$4:$AA$35,$AI$2)) -> 48 | AJ7: =(COUNTIF($C$4:$AA$35,$AJ$2))-0.5 -> 46.5 | AK7: 2 | AL7: =(COUNTIF($C$4:$AA$35,$AL$2)) -> 42 | AM7: =(COUNTIF($C$4:$AA$35,$AM$2))-0.5 -> 16.5 | AN7: 1 | AO7: =(COUNTIF($C$4:$AA$35,$AO$2)) -> 29 | AP7: =(COUNTIF($C$4:$AA$35,$AP$2)) -> 4 | AQ7: =(COUNTIF($C$4:$AA$35,$AQ$2)) -> 13 | AR7: =(COUNTIF($C$4:$AA$35,"SG")) -> 1
A8: 9h | B8: 18 JU | H8: A | I8: A | J8: A | K8: A | L8: A | AB8: 1 | AE8: Pondération (jour) | AF8: =AI8+AJ8+AL8+AM8+AO8+AQ8+AG8+AP8+AR8 -> 217 | AG8: =COUNTIF($C$4:$AA$4,$AG$2)*$AB$4+COUNTIF($C$5:$AA$5,$AG$2)*$AB$5+COUNTIF($C$6:$AA$6,$AG$2)*$AB$6+COUNTIF($C$7:$AA$7,$AG$2)*$AB$7+COUNTIF($C$8:$AA$8,$AG$2)*$AB$8+COUNTIF($C$9:$AA$9,$AG$2)*$AB$9+COUNTIF($C$10:$AA$10,$AG$2)*$AB$10+COUNTIF($C$11:$AA$11,$AG$2)*$AB$11+COUNTIF($C$12:$AA$12,$AG$2)*$AB$12+COUNTIF($C$13:$AA$13,$AG$2)*$AB$13+COUNTIF($C$14:$AA$14,$AG$2)*$AB$14+COUNTIF($C$15:$AA$15,$AG$2)*$AB$15+COUNTIF($C$16:$AA$16,$AG$2)*$AB$16+COUNTIF($C$17:$AA$17,$AG$2)*$AB$17+COUNTIF($C$18:$AA$18,$AG$2)*$AB$18+COUNTIF($C$19:$AA$19,$AG$2)*$AB$19+COUNTIF($C$20:$AA$20,$AG$2)*$AB$20+COUNTIF($C$21:$AA$21,$AG$2)*$AB$21+COUNTIF($C$22:$AA$22,$AG$2)*$AB$22+COUNTIF($C$23:$AA$23,$AG$2)*$AB$23+COUNTIF($C$24:$AA$24,$AG$2)*$AB$24+COUNTIF($C$25:$AA$25,$AG$2)*$AB$25+COUNTIF($C$26:$AA$26,$AG$2)*$AB$26+COUNTIF($C$27:$AA$27,$AG$2)*$AB$27+COUNTIF($C$28:$AA$28,$AG$2)*$AB$28+COUNTIF($C$29:$AA$29,$AG$2)*$AB$29+COUNTIF($C$30:$AA$30,$AG$2)*$AB$30+COUNTIF($C$31:$AA$31,$AG$2)*$AB$31+COUNTIF($C$32:$AA$32,$AG$2)*$AB$32+COUNTIF($C$33:$AA$33,$AG$2)*$AB$33+COUNTIF($C$34:$AA$34,$AG$2)*$AB$34 -> 2 | AH8: =4+4+4.25+7.125+3.25 -> 22.625 | AI8: =COUNTIF($C$4:$AA$4,$AI$2)*$AB$4+COUNTIF($C$5:$AA$5,$AI$2)*$AB$5+COUNTIF($C$6:$AA$6,$AI$2)*$AB$6+COUNTIF($C$7:$AA$7,$AI$2)*$AB$7+COUNTIF($C$8:$AA$8,$AI$2)*$AB$8+COUNTIF($C$9:$AA$9,$AI$2)*$AB$9+COUNTIF($C$10:$AA$10,$AI$2)*$AB$10+COUNTIF($C$11:$AA$11,$AI$2)*$AB$11+COUNTIF($C$12:$AA$12,$AI$2)*$AB$12+COUNTIF($C$13:$AA$13,$AI$2)*$AB$13+COUNTIF($C$14:$AA$14,$AI$2)*$AB$14+COUNTIF($C$15:$AA$15,$AI$2)*$AB$15+COUNTIF($C$16:$AA$16,$AI$2)*$AB$16+COUNTIF($C$17:$AA$17,$AI$2)*$AB$17+COUNTIF($C$18:$AA$18,$AI$2)*$AB$18+COUNTIF($C$19:$AA$19,$AI$2)*$AB$19+COUNTIF($C$20:$AA$20,$AI$2)*$AB$20+COUNTIF($C$21:$AA$21,$AI$2)*$AB$21+COUNTIF($C$22:$AA$22,$AI$2)*$AB$22+COUNTIF($C$23:$AA$23,$AI$2)*$AB$23+COUNTIF($C$24:$AA$24,$AI$2)*$AB$24+COUNTIF($C$25:$AA$25,$AI$2)*$AB$25+COUNTIF($C$26:$AA$26,$AI$2)*$AB$26+COUNTIF($C$27:$AA$27,$AI$2)*$AB$27+COUNTIF($C$28:$AA$28,$AI$2)*$AB$28+COUNTIF($C$29:$AA$29,$AI$2)*$AB$29+COUNTIF($C$30:$AA$30,$AI$2)*$AB$30+COUNTIF($C$31:$AA$31,$AI$2)*$AB$31+COUNTIF($C$32:$AA$32,$AI$2)*$AB$32+COUNTIF($C$33:$AA$33,$AI$2)*$AB$33+COUNTIF($C$34:$AA$34,$AI$2)*$AB$34 -> 52.5 | AJ8: =COUNTIF($C$4:$AA$4,AJ2)*$AB$4+COUNTIF($C$5:$AA$5,$AJ$2)*$AB$5+COUNTIF($C$6:$AA$6,$AJ$2)*$AB$6+COUNTIF($C$7:$AA$7,$AJ$2)*$AB$7+COUNTIF($C$8:$AA$8,$AJ$2)*$AB$8++COUNTIF($C$9:$AA$9,$AJ$2)*$AB$9+COUNTIF($C$10:$AA$10,$AJ$2)*$AB$10+COUNTIF($C$11:$AA$11,$AJ$2)*$AB$11+COUNTIF($C$12:$AA$12,$AJ$2)*$AB$12-0.25+COUNTIF($C$13:$AA$13,$AJ$2)*$AB$13+COUNTIF($C$14:$AA$14,$AJ$2)*$AB$14+COUNTIF($C$15:$AA$15,$AJ$2)*$AB$15+COUNTIF($C$16:$AA$16,$AJ$2)*$AB$16+COUNTIF($C$17:$AA$17,$AJ$2)*$AB$17+COUNTIF($C$18:$AA$18,$AJ$2)*$AB$18+COUNTIF($C$19:$AA$19,$AJ$2)*$AB$19+COUNTIF($C$20:$AA$20,$AJ$2)*$AB$20+COUNTIF($C$21:$AA$21,$AJ$2)*$AB$21+COUNTIF($C$22:$AA$22,$AJ$2)*$AB$22+COUNTIF($C$23:$AA$23,$AJ$2)*$AB$23+COUNTIF($C$24:$AA$24,$AJ$2)*$AB$24+COUNTIF($C$25:$AA$25,$AJ$2)*$AB$25+COUNTIF($C$26:$AA$26,$AJ$2)*$AB$26+COUNTIF($C$27:$AA$27,$AJ$2)*$AB$27+COUNTIF($C$28:$AA$28,$AJ$2)*$AB$28+COUNTIF($C$29:$AA$29,$AJ$2)*$AB$29+COUNTIF($C$30:$AA$30,$AJ$2)*$AB$30+COUNTIF($C$31:$AA$31,$AJ$2)*$AB$31+COUNTIF($C$32:$AA$32,$AJ$2)*$AB$32+COUNTIF($C$33:$AA$33,$AJ$2)*$AB$33+COUNTIF($C$34:$AA$34,$AJ$2)*$AB$34 -> 49 | AK8: =1.25+1.5 -> 2.75 | AL8: =COUNTIF($C$4:$AA$4,$AL$2)*$AB$4+COUNTIF($C$5:$AA$5,$AL$2)*$AB$5+COUNTIF($C$6:$AA$6,$AL$2)*$AB$6+COUNTIF($C$7:$AA$7,$AL$2)*$AB$7+COUNTIF($C$8:$AA$8,$AL$2)*$AB$8+COUNTIF($C$9:$AA$9,$AL$2)*$AB$9+COUNTIF($C$10:$AA$10,$AL$2)*$AB$10+COUNTIF($C$11:$AA$11,$AL$2)*$AB$11+COUNTIF($C$12:$AA$12,$AL$2)*$AB$12+COUNTIF($C$13:$AA$13,$AL$2)*$AB$13+COUNTIF($C$14:$AA$14,$AL$2)*$AB$14+COUNTIF($C$15:$AA$15,$AL$2)*$AB$15+COUNTIF($C$16:$AA$16,$AL$2)*$AB$16+COUNTIF($C$17:$AA$17,$AL$2)*$AB$17+COUNTIF($C$18:$AA$18,$AL$2)*$AB$18+COUNTIF($C$19:$AA$19,$AL$2)*$AB$19+COUNTIF($C$20:$AA$20,$AL$2)*$AB$20+COUNTIF($C$21:$AA$21,$AL$2)*$AB$21+COUNTIF($C$22:$AA$22,$AL$2)*$AB$22+COUNTIF($C$23:$AA$23,$AL$2)*$AB$23+COUNTIF($C$24:$AA$24,$AL$2)*$AB$24+COUNTIF($C$25:$AA$25,$AL$2)*$AB$25+COUNTIF($C$26:$AA$26,$AL$2)*$AB$26+COUNTIF($C$27:$AA$27,$AL$2)*$AB$27+COUNTIF($C$28:$AA$28,$AL$2)*$AB$28+COUNTIF($C$29:$AA$29,$AL$2)*$AB$29+COUNTIF($C$30:$AA$30,$AL$2)*$AB$96+COUNTIF($C$31:$AA$31,$AL$2)*$AB$31+COUNTIF($C$32:$AA$32,$AL$2)*$AB$32+COUNTIF($C$33:$AA$33,$AL$2)*$AB$33+COUNTIF($C$34:$AA$34,$AL$2)*$AB$34 -> 46 | AM8: =COUNTIF($C$4:$AA$4,$AM$2)*$AB$4+COUNTIF($C$5:$AA$5,$AM$2)*$AB$5+COUNTIF($C$6:$AA$6,$AM$2)*$AB$6+COUNTIF($C$7:$AA$7,$AM$2)*$AB$7+COUNTIF($C$8:$AA$8,$AM$2)*$AB$8+COUNTIF($C$9:$AA$9,$AM$2)*$AB$9+COUNTIF($C$10:$AA$10,$AM$2)*$AB$10+COUNTIF($C$11:$AA$11,$AM$2)*$AB$11+COUNTIF($C$12:$AA$12,$AM$2)*$AB$12-0.25+COUNTIF($C$13:$AA$13,$AM$2)*$AB$13+COUNTIF($C$14:$AA$14,$AM$2)*$AB$14+COUNTIF($C$15:$AA$15,$AM$2)*$AB$15+COUNTIF($C$16:$AA$16,$AM$2)*$AB$16+COUNTIF($C$17:$AA$17,$AM$2)*$AB$17+COUNTIF($C$18:$AA$18,$AM$2)*$AB$18+COUNTIF($C$19:$AA$19,$AM$2)*$AB$19+COUNTIF($C$20:$AA$20,$AM$2)*$AB$20+COUNTIF($C$21:$AA$21,$AM$2)*$AB$21+COUNTIF($C$22:$AA$22,$AM$2)*$AB$22+COUNTIF($C$23:$AA$23,$AM$2)*$AB$23+COUNTIF($C$24:$AA$24,$AM$2)*$AB$24+COUNTIF($C$25:$AA$25,$AM$2)*$AB$25+COUNTIF($C$26:$AA$26,$AM$2)*$AB$26+COUNTIF($C$27:$AA$27,$AM$2)*$AB$27+COUNTIF($C$28:$AA$28,$AM$2)*$AB$28+COUNTIF($C$29:$AA$29,$AM$2)*$AB$29+COUNTIF($C$30:$AA$30,$AM$2)*$AB$30+COUNTIF($C$31:$AA$31,$AM$2)*$AB$31+COUNTIF($C$32:$AA$32,$AM$2)*$AB$32+COUNTIF($C$33:$AA$33,$AM$2)*$AB$33+COUNTIF($C$34:$AA$34,$AM$2)*$AB$34 -> 22 | AN8: 1.5 | AO8: =COUNTIF($C$4:$AA$4,$AO$2)*$AB$4+COUNTIF($C$5:$AA$5,$AO$2)*$AB$5+COUNTIF($C$6:$AA$6,$AO$2)*$AB$6+COUNTIF($C$7:$AA$7,$AO$2)*$AB$7+COUNTIF($C$8:$AA$8,$AO$2)*$AB$8+COUNTIF($C$9:$AA$9,$AO$2)*$AB$9+COUNTIF($C$10:$AA$10,$AO$2)*$AB$10+COUNTIF($C$11:$AA$11,$AO$2)*$AB$11+COUNTIF($C$12:$AA$12,$AO$2)*$AB$12+COUNTIF($C$13:$AA$13,$AO$2)*$AB$13+COUNTIF($C$14:$AA$14,$AO$2)*$AB$14+COUNTIF($C$15:$AA$15,$AO$2)*$AB$15+COUNTIF($C$16:$AA$16,$AO$2)*$AB$16+COUNTIF($C$17:$AA$17,$AO$2)*$AB$17+COUNTIF($C$18:$AA$18,$AO$2)*$AB$18+COUNTIF($C$19:$AA$19,$AO$2)*$AB$19+COUNTIF($C$20:$AA$20,$AO$2)*$AB$20+COUNTIF($C$21:$AA$21,$AO$2)*$AB$21+COUNTIF($C$22:$AA$22,$AO$2)*$AB$22+COUNTIF($C$23:$AA$23,$AO$2)*$AB$23+COUNTIF($C$24:$AA$24,$AO$2)*$AB$24+COUNTIF($C$25:$AA$25,$AO$2)*$AB$25+COUNTIF($C$26:$AA$26,$AO$2)*$AB$26+COUNTIF($C$27:$AA$27,$AO$2)*$AB$27+COUNTIF($C$28:$AA$28,$AO$2)*$AB$28+COUNTIF($C$29:$AA$29,$AO$2)*$AB$29+COUNTIF($C$30:$AA$30,$AO$2)*$AB$30+COUNTIF($C$31:$AA$31,$AO$2)*$AB$31+COUNTIF($C$32:$AA$32,$AO$2)*$AB$32+COUNTIF($C$33:$AA$33,$AO$2)*$AB$33+COUNTIF($C$34:$AA$34,$AO$2)*$AB$34 -> 27.25 | AP8: =COUNTIF($C$4:$AA$4,$AP$2)*$AB$4+COUNTIF($C$5:$AA$5,$AP$2)*$AB$5+COUNTIF($C$6:$AA$6,$AP$2)*$AB$6+COUNTIF($C$7:$AA$7,$AP$2)*$AB$7+COUNTIF($C$8:$AA$8,$AP$2)*$AB$8+COUNTIF($C$9:$AA$9,$AP$2)*$AB$9+COUNTIF($C$10:$AA$10,$AP$2)*$AB$10+COUNTIF($C$11:$AA$11,$AP$2)*$AB$11+COUNTIF($C$12:$AA$12,$AP$2)*$AB$12+COUNTIF($C$13:$AA$13,$AP$2)*$AB$13+COUNTIF($C$14:$AA$14,$AP$2)*$AB$14+COUNTIF($C$15:$AA$15,$AP$2)*$AB$15+COUNTIF($C$16:$AA$16,$AP$2)*$AB$16+COUNTIF($C$17:$AA$17,$AP$2)*$AB$17+COUNTIF($C$18:$AA$18,$AP$2)*$AB$18+COUNTIF($C$19:$AA$19,$AP$2)*$AB$19+COUNTIF($C$20:$AA$20,$AP$2)*$AB$20+COUNTIF($C$21:$AA$21,$AP$2)*$AB$21+COUNTIF($C$22:$AA$22,$AP$2)*$AB$22+COUNTIF($C$23:$AA$23,$AP$2)*$AB$23+COUNTIF($C$24:$AA$24,$AP$2)*$AB$24+COUNTIF($C$25:$AA$25,$AP$2)*$AB$25+COUNTIF($C$26:$AA$26,$AP$2)*$AB$26+COUNTIF($C$27:$AA$27,$AP$2)*$AB$27+COUNTIF($C$28:$AA$28,$AP$2)*$AB$28+COUNTIF($C$29:$AA$29,$AP$2)*$AB$29+COUNTIF($C$30:$AA$30,$AP$2)*$AB$30+COUNTIF($C$31:$AA$31,$AP$2)*$AB$31+COUNTIF($C$32:$AA$32,$AP$2)*$AB$32+COUNTIF($C$33:$AA$33,$AP$2)*$AB$33+COUNTIF($C$34:$AA$34,$AP$2)*$AB$34 -> 5 | AQ8: =COUNTIF($C$4:$AA$4,$AQ$2)*$AB$4+COUNTIF($C$5:$AA$5,$AQ$2)*$AB$5+COUNTIF($C$6:$AA$6,$AQ$2)*$AB$6+COUNTIF($C$7:$AA$7,$AQ$2)*$AB$7+COUNTIF($C$8:$AA$8,$AQ$2)*$AB$8+COUNTIF($C$9:$AA$9,$AQ$2)*$AB$9+COUNTIF($C$10:$AA$10,$AQ$2)*$AB$10+COUNTIF($C$11:$AA$11,$AQ$2)*$AB$11+COUNTIF($C$12:$AA$12,$AQ$2)*$AB$12+COUNTIF($C$13:$AA$13,$AQ$2)*$AB$13+COUNTIF($C$14:$AA$14,$AQ$2)*$AB$14+COUNTIF($C$15:$AA$15,$AQ$2)*$AB$15+COUNTIF($C$16:$AA$16,$AQ$2)*$AB$16+COUNTIF($C$17:$AA$17,$AQ$2)*$AB$17+COUNTIF($C$18:$AA$18,$AQ$2)*$AB$18+COUNTIF($C$19:$AA$19,$AQ$2)*$AB$19+COUNTIF($C$20:$AA$20,$AQ$2)*$AB$20+COUNTIF($C$21:$AA$21,$AQ$2)*$AB$21+COUNTIF($C$22:$AA$22,$AQ$2)*$AB$22+COUNTIF($C$23:$AA$23,$AQ$2)*$AB$23+COUNTIF($C$24:$AA$24,$AQ$2)*$AB$24+COUNTIF($C$25:$AA$25,$AQ$2)*$AB$25+COUNTIF($C$26:$AA$26,$AQ$2)*$AB$26+COUNTIF($C$27:$AA$27,$AQ$2)*$AB$27+COUNTIF($C$28:$AA$28,$AQ$2)*$AB$28+COUNTIF($C$29:$AA$29,$AQ$2)*$AB$29+COUNTIF($C$30:$AA$30,$AQ$2)*$AB$30+COUNTIF($C$31:$AA$31,$AQ$2)*$AB$31+COUNTIF($C$32:$AA$32,$AQ$2)*$AB$32+COUNTIF($C$33:$AA$33,$AQ$2)*$AB$33+COUNTIF($C$34:$AA$34,$AQ$2)*$AB$34 -> 12 | AR8: =AR7*1.25 -> 1.25
A9: 9h | B9: 20 JU | M9: S | N9: A | O9: S | P9: S | Q9: S | AB9: 1 | AE9: Charge aud./mag. | AI9: =AI7/AI3 -> 6 | AJ9: =AJ7/AJ3 -> 6.6428571 | AL9: =AL7/AL3 -> 7 | AM9: =AM7/AM3 -> 4.125 | AO9: =AO7/AO3 -> 7.25 | AP9: =AP7/AP3 -> 2 | AQ9: =AQ7/AQ3 -> 6.5 | AR9: =AR7/AR3 -> 1
A10: 9h | B10: 20 Coll | E10: M | AB10: 1.5 | AE10: Ch. aud. pond./mag. | AF10: =(AF8-AH8)/AF4 -> 5.8901515 | AG10: =AG8/AG4 -> 2 | AI10: =(AI8-4)/AI4 -> 6.0625 | AJ10: =(AJ8-1.75)/AJ4 -> 6.75 | AK10: =(AK8)/AK3 -> 2.75 | AL10: =(AL8-4)/AL4 -> 7 | AM10: =(AM8-7.125)/AM4 -> 3.71875 | AN10: =(AN8)/AN4 -> 1.5 | AO10: =(AO8-3.25)/AO4 -> 6 | AP10: =AP8/AP4 -> 2.5 | AQ10: =(AQ8)/AQ4 -> 6 | AR10: =AR8/AR4 -> 1.25
A11: 9h | B11: 21 Coll | AB11: 1.5 | AE11: 1/2 jour perm. de semaine | AF11: =AI11+AJ11+AL11+AM11+AO11+AQ11 -> 400 | AI11: =25*2*2 -> 100 | AJ11: =25*2*2 -> 100 | AK11: 1 | AL11: =25*2 -> 50 | AM11: =25*2 -> 50 | AO11: =25*2 -> 50 | AQ11: =25*2 -> 50
A12: 9h | B12: CRPC | M12: PR | N12: E | O12: PR | P12: PR | Q12: PR | R12: A | S12: M | T12: A | U12: S | AB12: 0.5 | AE12: 1/2 journée perm/mag. | AF12: =(AF11-9)/AF3 -> 10.025641 | AG12: =AG11/AG3 -> 0 | AI12: =AI11/AI3 -> 12.5 | AJ12: =AJ11/AJ3 -> 14.285714 | AK12: =AK3*25 -> 25 | AL12: =AL11/AL3 -> 8.3333333 | AM12: =AM11/AM3 -> 12.5 | AO12: =AO11/AO3 -> 12.5 | AP12: =AP11/AP3 -> 0 | AQ12: =AQ11/AQ3 -> 25 | AR12: =AR11/AR3 -> 0
A13: 9h | B13: TPE | D13: M | F13: M | H13: M | I13: M | J13: M | K13: M | L13: M | M13: M | N13: M | O13: M | P13: M | Q13: M | R13: M | S13: M | T13: M | U13: M | V13: M | AB13: 1 | AE13: total 1/2 journées cabinet | AF13: =AF5-AF8-AF11 -> 183 | AI13: =AI5-AI8-AI11 -> 47.5 | AJ13: =AJ5-AJ8-AJ11 -> 26 | AL13: =AL5-AL8-AL11 -> 54 | AM13: =AM5-AM8-AM11 -> 28 | AO13: =AO5-AO8-AO11 -> 22.75 | AP13: =AP5-AP8-AP11 -> 45 | AQ13: =AQ5-AQ8-AQ11 -> -12 | AR13: =AR5-AR8-AR11 -> 23.75
A14: 13h30 | B14: 12 Coll | N14: S | R14: S | S14: S | T14: S | U14: S | V14: S | W14: S | X14: S | Y14: S | Z14: S | AA14: S | AB14: 1.5 | AE14: 1/2 cab/magistrat | AF14: =AF13/33 -> 5.5454545 | AI14: =AI13/AI3 -> 5.9375 | AJ14: =AJ13/AJ3 -> 3.7142857 | AL14: =AL13/AL3 -> 9 | AM14: =AM13/AM3 -> 7 | AO14: =AO13/AO3 -> 5.6875 | AP14: =AP13/AP3 -> 22.5 | AQ14: =AQ13/AQ3 -> -6 | AR14: =AR13/AR3 -> 23.75
A15: 13h30 | B15: 14 Coll | H15: J | I15: E | J15: E | K15: E | L15: E | N15: E | P15: E | AB15: 1.5 | AE15: Jours de cab/mois/mag. | AF15: =AF14/2 -> 2.7727273 | AI15: =AI14/2 -> 2.96875 | AJ15: =AJ14/2 -> 1.8571429 | AL15: =AL14/2 -> 4.5 | AM15: =AM14/2 -> 3.5 | AO15: =AO14/2 -> 2.84375 | AQ15: =AQ14/2 -> -3
A16: 13h30 | B16: 15 Coll | R16: E | S16: E | T16: E | U16: E | V16: E | W16: E | X16: E | Y16: E | Z16: E | AA16: E | AB16: 1.5
A17: 13h30 | B17: 16 – CI | C17: A | D17: A | E17: S | F17: A | G17: A | H17: E | I17: P | J17: P | K17: P | L17: P | M17: A | N17: A | O17: A | P17: A | Q17: A | R17: A | S17: A | T17: N | U17: N | V17: M | W17: N | X17: SG | Y17: V | Z17: N | AA17: A | AB17: 1.25
A18: 13h30 | B18: 17 Coll | C18: E | D18: E | E18: A | F18: E | G18: A | AB18: 1.5 | AD18: Pondération :
A19: 13h30 | B19: 18 Coll | H19: A | I19: A | J19: A | K19: A | L19: A | R19: C | S19: C | T19: C | U19: C | V19: C | AB19: 1.5 | AD19: 1 JU = 1 audience civile = 1 CAP/DCMF = 1 TPE (d’une demi-journée) = 1 journée
A20: 13h30 | B20: 20 JU | J20: M | AB20: 1 | AD20: D5 : A voir les CAP LSC = 1 jour
A21: 13h30 | B21: 20 Coll | C21: V | D21: M | E21: M | F21: M | G21: M | AB21: 1.5 | AD21: 1 CRPC = 1 Tpol = 1 audience procédures collectives TJ = 0,5 journée
A22: 13h30 | B22: 21 Coll | AB22: 1.5 | AD22: 1 Tcom = 1 CAP = 0,75 journée
A23: 13h30 | B23: T.Pol | C23: A | E23: A | AB23: 0.5 | AD23: 1 Coll = 1,5 journées
A24: 13h30 | B24: TPE | F24: M | H24: M | I24: M | J24: M | K24: M | L24: M | M24: M | N24: M | O24: M | P24: M | Q24: M | R24: M | S24: M | T24: M | U24: M | V24: M | AB24: 1 | AD24: 1 CI = 1,25 journée (compte tenu de la tardiveté)
A25: 9h30 | B25: Aud. Civ. | H25: C | J25: C | K25: C | AB25: 0.5 | AD25: 1 journée d’assises = 2 jour (1 jour de prépa + 1 jour d’audience si le parquetier n’est pas le régleur= ou 1,5 jour (si c’est le régleur)
A26: 13h30 | B26: Aud. Civ. | C26: C | E26: C | M26: C | T26: C | AB26: 0.5 | AD26: Audiences spéciales : même calcul que pour les journées d’assises ?
A27: 9h | B27: CAP | H27: P | R27: P | S27: P | T27: P | U27: P | AB27: 0.75
A28: 13h30 | B28: CAP | R28: P | S28: P | T28: P | U28: P | AB28: 0.75
A29: 13h30 | B29: DCMO | C29: P | D29: P | E29: P | F29: P | G29: P | M29: P | N29: P | O29: P | P29: P | Q29: P | AB29: 1
A30: 14h | B30: DCMF | R30: P | S30: P | T30: P | U30: P | V30: P | AB30: 1
A31: 13h30 | B31: CJ | X31: P | AB31: 0.5
A32: 9h | B32: TJ | X32: E | Z32: E | AB32: 0.5
A33: 9h | B33: T Com | H33: E | I33: E | J33: E | K33: E | L33: E | M33: E | N33: E | O33: E | P33: E | Q33: E | R33: E | S33: E | T33: E | U33: E | V33: E | AB33: 0.75
A34: 13h30 | B34: T Com | H34: E | T34: E | AB34: 0.75

Sheet Réforme
B1: Tableau de répartition des audiences entre les divisions du parquet (réforme janvier 2025) | AF1: PR | AG1: PRA | AH1: PAP | AI1: PMF | AJ1: V. Deneux | AK1: DEF | AL1: COFAC | AM1: JP Oualid | AN1: EP | AO1: PCC | AP1: Civil | AQ1: SG
E2: LUNDI | J2: MARDI | O2: MERCREDI | T2: JEUDI | Y2: VENDREDI | AB2: Pond. | AE2: Parquet | AF2: PR | AG2: PRA | AH2: A | AI2: M | AJ2: V | AK2: E | AL2: S | AM2: J | AN2: P | AO2: N | AP2: C | AQ2: SG
C3: 1 | D3: 2 | E3: 3 | F3: 4 | G3: 5 | H3: 1 | I3: 2 | J3: 3 | K3: 4 | L3: 5 | M3: 1 | N3: 2 | O3: 3 | P3: 4 | Q3: 5 | R3: 1 | S3: 2 | T3: 3 | U3: 4 | V3: 5 | W3: 1 | X3: 2 | Y3: 3 | Z3: 4 | AA3: 5 | AD3: ETPT mag. Parquet | AE3: 39 | AF3: 1 | AG3: 5 | AH3: 8 | AI3: 7 | AJ3: 1 | AK3: 6 | AL3: 4 | AM3: 1 | AN3: 4 | AO3: 2 | AP3: 2 | AQ3: 1
A4: 9h | B4: 11 JU | C4: A | D4: A | F4: A | G4: A | I4: A | J4: A | L4: A | AB4: =1 -> 1 | AD4: ETPT de perm/audiences | AE4: 33 | AF4: 1 | AH4: 8 | AI4: 7 | AJ4: 1 | AK4: 6 | AL4: 4 | AM4: 1 | AN4: 4 | AO4: 2 | AP4: 2 | AQ4: 1
A5: 9h | B5: 11 Coll | K5: A | AB5: 1.5 | AD5: total 1/2 journées (hors Hier.) | AE5: =(AE3-7)*25 -> 800 | AF5: =AF3*25 -> 25 | AG5: =AG3*25 -> 125 | AH5: =AH3*25 -> 200 | AI5: =AI3*25 -> 175 | AJ5: =AJ3*25 -> 25 | AK5: =AK3*25 -> 150 | AL5: =AL3*25 -> 100 | AM5: =AM3*25 -> 25 | ... AQ5: =AQ3*25 -> 25
A6: 9h | B6: 12 JU | W6: S | Y6: S | Z6: S | AA6: S | AB6: 1
A7: 9h | B7: 18 JU | H7: A | I7: A | J7: A | K7: A | M7: A | N7: A | O7: A | P7: A | Q7: V | W7: A | X7: A | Y7: A | Z7: A | AA7: A | AB7: 1 | AD7: 1/2 j d'audiences (Tcorr, TPE, Tpol, Tcom.) | AE7: 156 | AF7: =(COUNTIF($C$4:$AA$33,$AF$2)) -> 0 | AH7: =(COUNTIF($C$4:$AA$33,$AH$2)) -> 50 | AI7: =(COUNTIF($C$4:$AA$33,$AI$2)) -> 52 | AJ7: =(COUNTIF($C$4:$AA$33,$AJ$2)) -> 6 | AK7: =(COUNTIF($C$4:$AA$33,$AK$2)) -> 40 | AL7: =(COUNTIF($C$4:$AA$33,$AL$2)) -> 17 | AM7: =(COUNTIF($C$4:$AA$33,$AM$2)) -> 2 | AN7: =(COUNTIF($C$4:$AA$33,$AN$2)) -> 29 | AO7: =(COUNTIF($C$4:$AA$33,$AO$2)) -> 4 | AP7: =(COUNTIF($C$4:$AA$33,$AP$2)) -> 7 | AQ7: =(COUNTIF($C$4:$AA$33,"SG")) -> 1
